Workbook

Sheet 最新流水
A1: 序号 | B1: 期号 | C1: 原始记录 | D1: 命中金额 | E1: 亏损金额 | F1: 净额 | G1: 开奖时间 | H1: 实际特码 | I1: 实际生肖 | J1: 自动结果 | K1: 备注 | L1: 平码+5建议 | M1: 加5验算 | N1: 八肖建议 | O1: 八肖验算
A2: =IF($B2="","",1) | B2: =IFERROR(LARGE(智能流水!$B$2:$B$1001,1),"") | C2: =IF($B2="","",IFERROR(INDEX(智能流水!$C$2:$C$1001,MATCH($B2,智能流水!$B$2:$B$1001,0)),"")) | D2: =IF($B2="","",IFERROR(INDEX(智能流水!$D$2:$D$1001,MATCH($B2,智能流水!$B$2:$B$1001,0)),"")) | E2: =IF($B2="","",IFERROR(INDEX(智能流水!$E$2:$E$1001,MATCH($B2,智能流水!$B$2:$B$1001,0)),"")) | F2: =IF($B2="","",IFERROR(INDEX(智能流水!$F$2:$F$1001,MATCH($B2,智能流水!$B$2:$B$1001,0)),"")) | G2: =IF($B2="","",IFERROR(INDEX(智能流水!$G$2:$G$1001,MATCH($B2,智能流水!$B$2:$B$1001,0)),"")) | H2: =IF($B2="","",IFERROR(INDEX(智能流水!$H$2:$H$1001,MATCH($B2,智能流水!$B$2:$B$1001,0)),"")) | I2: =IF($B2="","",IFERROR(INDEX(智能流水!$I$2:$I$1001,MATCH($B2,智能流水!$B$2:$B$1001,0)),"")) | J2: =IF($B2="","",IFERROR(INDEX(智能流水!$J$2:$J$1001,MATCH($B2,智能流水!$B$2:$B$1001,0)),"")) | K2: =IF($B2="","",IFERROR(INDEX(智能流水!$K$2:$K$1001,MATCH($B2,智能流水!$B$2:$B$1001,0)),"")) | L2: =IF($B2="","",IFERROR(INDEX(智能流水!$L$2:$L$1001,MATCH($B2,智能流水!$B$2:$B$1001,0)),"")) | M2: =IF($B2="","",IFERROR(INDEX(智能流水!$M$2:$M$1001,MATCH($B2,智能流水!$B$2:$B$1001,0)),"")) | N2: =IF($B2="","",IFERROR(INDEX(智能流水!$N$2:$N$1001,MATCH($B2,智能流水!$B$2:$B$1001,0)),"")) | O2: =IF($B2="","",IFERROR(INDEX(智能流水!$O$2:$O$1001,MATCH($B2,智能流水!$B$2:$B$1001,0)),""))
A3: =IF($B3="","",2) | B3: =IFERROR(LARGE(智能流水!$B$2:$B$1001,2),"") | C3: =IF($B3="","",IFERROR(INDEX(智能流水!$C$2:$C$1001,MATCH($B3,智能流水!$B$2:$B$1001,0)),"")) | D3: =IF($B3="","",IFERROR(INDEX(智能流水!$D$2:$D$1001,MATCH($B3,智能流水!$B$2:$B$1001,0)),"")) | E3: =IF($B3="","",IFERROR(INDEX(智能流水!$E$2:$E$1001,MATCH($B3,智能流水!$B$2:$B$1001,0)),"")) | F3: =IF($B3="","",IFERROR(INDEX(智能流水!$F$2:$F$1001,MATCH($B3,智能流水!$B$2:$B$1001,0)),"")) | G3: =IF($B3="","",IFERROR(INDEX(智能流水!$G$2:$G$1001,MATCH($B3,智能流水!$B$2:$B$1001,0)),"")) | H3: =IF($B3="","",IFERROR(INDEX(智能流水!$H$2:$H$1001,MATCH($B3,智能流水!$B$2:$B$1001,0)),"")) | I3: =IF($B3="","",IFERROR(INDEX(智能流水!$I$2:$I$1001,MATCH($B3,智能流水!$B$2:$B$1001,0)),"")) | J3: =IF($B3="","",IFERROR(INDEX(智能流水!$J$2:$J$1001,MATCH($B3,智能流水!$B$2:$B$1001,0)),"")) | K3: =IF($B3="","",IFERROR(INDEX(智能流水!$K$2:$K$1001,MATCH($B3,智能流水!$B$2:$B$1001,0)),"")) | L3: =IF($B3="","",IFERROR(INDEX(智能流水!$L$2:$L$1001,MATCH($B3,智能流水!$B$2:$B$1001,0)),"")) | M3: =IF($B3="","",IFERROR(INDEX(智能流水!$M$2:$M$1001,MATCH($B3,智能流水!$B$2:$B$1001,0)),"")) | N3: =IF($B3="","",IFERROR(INDEX(智能流水!$N$2:$N$1001,MATCH($B3,智能流水!$B$2:$B$1001,0)),"")) | O3: =IF($B3="","",IFERROR(INDEX(智能流水!$O$2:$O$1001,MATCH($B3,智能流水!$B$2:$B$1001,0)),""))
A4: =IF($B4="","",3) | B4: =IFERROR(LARGE(智能流水!$B$2:$B$1001,3),"") | C4: =IF($B4="","",IFERROR(INDEX(智能流水!$C$2:$C$1001,MATCH($B4,智能流水!$B$2:$B$1001,0)),"")) | D4: =IF($B4="","",IFERROR(INDEX(智能流水!$D$2:$D$1001,MATCH($B4,智能流水!$B$2:$B$1001,0)),"")) | E4: =IF($B4="","",IFERROR(INDEX(智能流水!$E$2:$E$1001,MATCH($B4,智能流水!$B$2:$B$1001,0)),"")) | F4: =IF($B4="","",IFERROR(INDEX(智能流水!$F$2:$F$1001,MATCH($B4,智能流水!$B$2:$B$1001,0)),"")) | G4: =IF($B4="","",IFERROR(INDEX(智能流水!$G$2:$G$1001,MATCH($B4,智能流水!$B$2:$B$1001,0)),"")) | H4: =IF($B4="","",IFERROR(INDEX(智能流水!$H$2:$H$1001,MATCH($B4,智能流水!$B$2:$B$1001,0)),"")) | I4: =IF($B4="","",IFERROR(INDEX(智能流水!$I$2:$I$1001,MATCH($B4,智能流水!$B$2:$B$1001,0)),"")) | J4: =IF($B4="","",IFERROR(INDEX(智能流水!$J$2:$J$1001,MATCH($B4,智能流水!$B$2:$B$1001,0)),"")) | K4: =IF($B4="","",IFERROR(INDEX(智能流水!$K$2:$K$1001,MATCH($B4,智能流水!$B$2:$B$1001,0)),"")) | L4: =IF($B4="","",IFERROR(INDEX(智能流水!$L$2:$L$1001,MATCH($B4,智能流水!$B$2:$B$1001,0)),"")) | M4: =IF($B4="","",IFERROR(INDEX(智能流水!$M$2:$M$1001,MATCH($B4,智能流水!$B$2:$B$1001,0)),"")) | N4: =IF($B4="","",IFERROR(INDEX(智能流水!$N$2:$N$1001,MATCH($B4,智能流水!$B$2:$B$1001,0)),"")) | O4: =IF($B4="","",IFERROR(INDEX(智能流水!$O$2:$O$1001,MATCH($B4,智能流水!$B$2:$B$1001,0)),""))
A5: =IF($B5="","",4) | B5: =IFERROR(LARGE(智能流水!$B$2:$B$1001,4),"") | C5: =IF($B5="","",IFERROR(INDEX(智能流水!$C$2:$C$1001,MATCH($B5,智能流水!$B$2:$B$1001,0)),"")) | D5: =IF($B5="","",IFERROR(INDEX(智能流水!$D$2:$D$1001,MATCH($B5,智能流水!$B$2:$B$1001,0)),"")) | E5: =IF($B5="","",IFERROR(INDEX(智能流水!$E$2:$E$1001,MATCH($B5,智能流水!$B$2:$B$1001,0)),"")) | F5: =IF($B5="","",IFERROR(INDEX(智能流水!$F$2:$F$1001,MATCH($B5,智能流水!$B$2:$B$1001,0)),"")) | G5: =IF($B5="","",IFERROR(INDEX(智能流水!$G$2:$G$1001,MATCH($B5,智能流水!$B$2:$B$1001,0)),"")) | H5: =IF($B5="","",IFERROR(INDEX(智能流水!$H$2:$H$1001,MATCH($B5,智能流水!$B$2:$B$1001,0)),"")) | I5: =IF($B5="","",IFERROR(INDEX(智能流水!$I$2:$I$1001,MATCH($B5,智能流水!$B$2:$B$1001,0)),"")) | J5: =IF($B5="","",IFERROR(INDEX(智能流水!$J$2:$J$1001,MATCH($B5,智能流水!$B$2:$B$1001,0)),"")) | K5: =IF($B5="","",IFERROR(INDEX(智能流水!$K$2:$K$1001,MATCH($B5,智能流水!$B$2:$B$1001,0)),"")) | L5: =IF($B5="","",IFERROR(INDEX(智能流水!$L$2:$L$1001,MATCH($B5,智能流水!$B$2:$B$1001,0)),"")) | M5: =IF($B5="","",IFERROR(INDEX(智能流水!$M$2:$M$1001,MATCH($B5,智能流水!$B$2:$B$1001,0)),"")) | N5: =IF($B5="","",IFERROR(INDEX(智能流水!$N$2:$N$1001,MATCH($B5,智能流水!$B$2:$B$1001,0)),"")) | O5: =IF($B5="","",IFERROR(INDEX(智能流水!$O$2:$O$1001,MATCH($B5,智能流水!$B$2:$B$1001,0)),""))
A6: =IF($B6="","",5) | B6: =IFERROR(LARGE(智能流水!$B$2:$B$1001,5),"") | C6: =IF($B6="","",IFERROR(INDEX(智能流水!$C$2:$C$1001,MATCH($B6,智能流水!$B$2:$B$1001,0)),"")) | D6: =IF($B6="","",IFERROR(INDEX(智能流水!$D$2:$D$1001,MATCH($B6,智能流水!$B$2:$B$1001,0)),"")) | E6: =IF($B6="","",IFERROR(INDEX(智能流水!$E$2:$E$1001,MATCH($B6,智能流水!$B$2:$B$1001,0)),"")) | F6: =IF($B6="","",IFERROR(INDEX(智能流水!$F$2:$F$1001,MATCH($B6,智能流水!$B$2:$B$1001,0)),"")) | G6: =IF($B6="","",IFERROR(INDEX(智能流水!$G$2:$G$1001,MATCH($B6,智能流水!$B$2:$B$1001,0)),"")) | H6: =IF($B6="","",IFERROR(INDEX(智能流水!$H$2:$H$1001,MATCH($B6,智能流水!$B$2:$B$1001,0)),"")) | I6: =IF($B6="","",IFERROR(INDEX(智能流水!$I$2:$I$1001,MATCH($B6,智能流水!$B$2:$B$1001,0)),"")) | J6: =IF($B6="","",IFERROR(INDEX(智能流水!$J$2:$J$1001,MATCH($B6,智能流水!$B$2:$B$1001,0)),"")) | K6: =IF($B6="","",IFERROR(INDEX(智能流水!$K$2:$K$1001,MATCH($B6,智能流水!$B$2:$B$1001,0)),"")) | L6: =IF($B6="","",IFERROR(INDEX(智能流水!$L$2:$L$1001,MATCH($B6,智能流水!$B$2:$B$1001,0)),"")) | M6: =IF($B6="","",IFERROR(INDEX(智能流水!$M$2:$M$1001,MATCH($B6,智能流水!$B$2:$B$1001,0)),"")) | N6: =IF($B6="","",IFERROR(INDEX(智能流水!$N$2:$N$1001,MATCH($B6,智能流水!$B$2:$B$1001,0)),"")) | O6: =IF($B6="","",IFERROR(INDEX(智能流水!$O$2:$O$1001,MATCH($B6,智能流水!$B$2:$B$1001,0)),""))
A7: =IF($B7="","",6) | B7: =IFERROR(LARGE(智能流水!$B$2:$B$1001,6),"") | C7: =IF($B7="","",IFERROR(INDEX(智能流水!$C$2:$C$1001,MATCH($B7,智能流水!$B$2:$B$1001,0)),"")) | D7: =IF($B7="","",IFERROR(INDEX(智能流水!$D$2:$D$1001,MATCH($B7,智能流水!$B$2:$B$1001,0)),"")) | E7: =IF($B7="","",IFERROR(INDEX(智能流水!$E$2:$E$1001,MATCH($B7,智能流水!$B$2:$B$1001,0)),"")) | F7: =IF($B7="","",IFERROR(INDEX(智能流水!$F$2:$F$1001,MATCH($B7,智能流水!$B$2:$B$1001,0)),"")) | G7: =IF($B7="","",IFERROR(INDEX(智能流水!$G$2:$G$1001,MATCH($B7,智能流水!$B$2:$B$1001,0)),"")) | H7: =IF($B7="","",IFERROR(INDEX(智能流水!$H$2:$H$1001,MATCH($B7,智能流水!$B$2:$B$1001,0)),"")) | I7: =IF($B7="","",IFERROR(INDEX(智能流水!$I$2:$I$1001,MATCH($B7,智能流水!$B$2:$B$1001,0)),"")) | J7: =IF($B7="","",IFERROR(INDEX(智能流水!$J$2:$J$1001,MATCH($B7,智能流水!$B$2:$B$1001,0)),"")) | K7: =IF($B7="","",IFERROR(INDEX(智能流水!$K$2:$K$1001,MATCH($B7,智能流水!$B$2:$B$1001,0)),"")) | L7: =IF($B7="","",IFERROR(INDEX(智能流水!$L$2:$L$1001,MATCH($B7,智能流水!$B$2:$B$1001,0)),"")) | M7: =IF($B7="","",IFERROR(INDEX(智能流水!$M$2:$M$1001,MATCH($B7,智能流水!$B$2:$B$1001,0)),"")) | N7: =IF($B7="","",IFERROR(INDEX(智能流水!$N$2:$N$1001,MATCH($B7,智能流水!$B$2:$B$1001,0)),"")) | O7: =IF($B7="","",IFERROR(INDEX(智能流水!$O$2:$O$1001,MATCH($B7,智能流水!$B$2:$B$1001,0)),""))
A8: =IF($B8="","",7) | B8: =IFERROR(LARGE(智能流水!$B$2:$B$1001,7),"") | C8: =IF($B8="","",IFERROR(INDEX(智能流水!$C$2:$C$1001,MATCH($B8,智能流水!$B$2:$B$1001,0)),"")) | D8: =IF($B8="","",IFERROR(INDEX(智能流水!$D$2:$D$1001,MATCH($B8,智能流水!$B$2:$B$1001,0)),"")) | E8: =IF($B8="","",IFERROR(INDEX(智能流水!$E$2:$E$1001,MATCH($B8,智能流水!$B$2:$B$1001,0)),"")) | F8: =IF($B8="","",IFERROR(INDEX(智能流水!$F$2:$F$1001,MATCH($B8,智能流水!$B$2:$B$1001,0)),"")) | G8: =IF($B8="","",IFERROR(INDEX(智能流水!$G$2:$G$1001,MATCH($B8,智能流水!$B$2:$B$1001,0)),"")) | H8: =IF($B8="","",IFERROR(INDEX(智能流水!$H$2:$H$1001,MATCH($B8,智能流水!$B$2:$B$1001,0)),"")) | I8: =IF($B8="","",IFERROR(INDEX(智能流水!$I$2:$I$1001,MATCH($B8,智能流水!$B$2:$B$1001,0)),"")) | J8: =IF($B8="","",IFERROR(INDEX(智能流水!$J$2:$J$1001,MATCH($B8,智能流水!$B$2:$B$1001,0)),"")) | K8: =IF($B8="","",IFERROR(INDEX(智能流水!$K$2:$K$1001,MATCH($B8,智能流水!$B$2:$B$1001,0)),"")) | L8: =IF($B8="","",IFERROR(INDEX(智能流水!$L$2:$L$1001,MATCH($B8,智能流水!$B$2:$B$1001,0)),"")) | M8: =IF($B8="","",IFERROR(INDEX(智能流水!$M$2:$M$1001,MATCH($B8,智能流水!$B$2:$B$1001,0)),"")) | N8: =IF($B8="","",IFERROR(INDEX(智能流水!$N$2:$N$1001,MATCH($B8,智能流水!$B$2:$B$1001,0)),"")) | O8: =IF($B8="","",IFERROR(INDEX(智能流水!$O$2:$O$1001,MATCH($B8,智能流水!$B$2:$B$1001,0)),""))
A9: =IF($B9="","",8) | B9: =IFERROR(LARGE(智能流水!$B$2:$B$1001,8),"") | C9: =IF($B9="","",IFERROR(INDEX(智能流水!$C$2:$C$1001,MATCH($B9,智能流水!$B$2:$B$1001,0)),"")) | D9: =IF($B9="","",IFERROR(INDEX(智能流水!$D$2:$D$1001,MATCH($B9,智能流水!$B$2:$B$1001,0)),"")) | E9: =IF($B9="","",IFERROR(INDEX(智能流水!$E$2:$E$1001,MATCH($B9,智能流水!$B$2:$B$1001,0)),"")) | F9: =IF($B9="","",IFERROR(INDEX(智能流水!$F$2:$F$1001,MATCH($B9,智能流水!$B$2:$B$1001,0)),"")) | G9: =IF($B9="","",IFERROR(INDEX(智能流水!$G$2:$G$1001,MATCH($B9,智能流水!$B$2:$B$1001,0)),"")) | H9: =IF($B9="","",IFERROR(INDEX(智能流水!$H$2:$H$1001,MATCH($B9,智能流水!$B$2:$B$1001,0)),"")) | I9: =IF($B9="","",IFERROR(INDEX(智能流水!$I$2:$I$1001,MATCH($B9,智能流水!$B$2:$B$1001,0)),"")) | J9: =IF($B9="","",IFERROR(INDEX(智能流水!$J$2:$J$1001,MATCH($B9,智能流水!$B$2:$B$1001,0)),"")) | K9: =IF($B9="","",IFERROR(INDEX(智能流水!$K$2:$K$1001,MATCH($B9,智能流水!$B$2:$B$1001,0)),"")) | L9: =IF($B9="","",IFERROR(INDEX(智能流水!$L$2:$L$1001,MATCH($B9,智能流水!$B$2:$B$1001,0)),"")) | M9: =IF($B9="","",IFERROR(INDEX(智能流水!$M$2:$M$1001,MATCH($B9,智能流水!$B$2:$B$1001,0)),"")) | N9: =IF($B9="","",IFERROR(INDEX(智能流水!$N$2:$N$1001,MATCH($B9,智能流水!$B$2:$B$1001,0)),"")) | O9: =IF($B9="","",IFERROR(INDEX(智能流水!$O$2:$O$1001,MATCH($B9,智能流水!$B$2:$B$1001,0)),""))
A10: =IF($B10="","",9) | B10: =IFERROR(LARGE(智能流水!$B$2:$B$1001,9),"") | C10: =IF($B10="","",IFERROR(INDEX(智能流水!$C$2:$C$1001,MATCH($B10,智能流水!$B$2:$B$1001,0)),"")) | D10: =IF($B10="","",IFERROR(INDEX(智能流水!$D$2:$D$1001,MATCH($B10,智能流水!$B$2:$B$1001,0)),"")) | E10: =IF($B10="","",IFERROR(INDEX(智能流水!$E$2:$E$1001,MATCH($B10,智能流水!$B$2:$B$1001,0)),"")) | F10: =IF($B10="","",IFERROR(INDEX(智能流水!$F$2:$F$1001,MATCH($B10,智能流水!$B$2:$B$1001,0)),"")) | G10: =IF($B10="","",IFERROR(INDEX(智能流水!$G$2:$G$1001,MATCH($B10,智能流水!$B$2:$B$1001,0)),"")) | H10: =IF($B10="","",IFERROR(INDEX(智能流水!$H$2:$H$1001,MATCH($B10,智能流水!$B$2:$B$1001,0)),"")) | I10: =IF($B10="","",IFERROR(INDEX(智能流水!$I$2:$I$1001,MATCH($B10,智能流水!$B$2:$B$1001,0)),"")) | J10: =IF($B10="","",IFERROR(INDEX(智能流水!$J$2:$J$1001,MATCH($B10,智能流水!$B$2:$B$1001,0)),"")) | K10: =IF($B10="","",IFERROR(INDEX(智能流水!$K$2:$K$1001,MATCH($B10,智能流水!$B$2:$B$1001,0)),"")) | L10: =IF($B10="","",IFERROR(INDEX(智能流水!$L$2:$L$1001,MATCH($B10,智能流水!$B$2:$B$1001,0)),"")) | M10: =IF($B10="","",IFERROR(INDEX(智能流水!$M$2:$M$1001,MATCH($B10,智能流水!$B$2:$B$1001,0)),"")) | N10: =IF($B10="","",IFERROR(INDEX(智能流水!$N$2:$N$1001,MATCH($B10,智能流水!$B$2:$B$1001,0)),"")) | O10: =IF($B10="","",IFERROR(INDEX(智能流水!$O$2:$O$1001,MATCH($B10,智能流水!$B$2:$B$1001,0)),""))
A11: =IF($B11="","",10) | B11: =IFERROR(LARGE(智能流水!$B$2:$B$1001,10),"") | C11: =IF($B11="","",IFERROR(INDEX(智能流水!$C$2:$C$1001,MATCH($B11,智能流水!$B$2:$B$1001,0)),"")) | D11: =IF($B11="","",IFERROR(INDEX(智能流水!$D$2:$D$1001,MATCH($B11,智能流水!$B$2:$B$1001,0)),"")) | E11: =IF($B11="","",IFERROR(INDEX(智能流水!$E$2:$E$1001,MATCH($B11,智能流水!$B$2:$B$1001,0)),"")) | F11: =IF($B11="","",IFERROR(INDEX(智能流水!$F$2:$F$1001,MATCH($B11,智能流水!$B$2:$B$1001,0)),"")) | G11: =IF($B11="","",IFERROR(INDEX(智能流水!$G$2:$G$1001,MATCH($B11,智能流水!$B$2:$B$1001,0)),"")) | H11: =IF($B11="","",IFERROR(INDEX(智能流水!$H$2:$H$1001,MATCH($B11,智能流水!$B$2:$B$1001,0)),"")) | I11: =IF($B11="","",IFERROR(INDEX(智能流水!$I$2:$I$1001,MATCH($B11,智能流水!$B$2:$B$1001,0)),"")) | J11: =IF($B11="","",IFERROR(INDEX(智能流水!$J$2:$J$1001,MATCH($B11,智能流水!$B$2:$B$1001,0)),"")) | K11: =IF($B11="","",IFERROR(INDEX(智能流水!$K$2:$K$1001,MATCH($B11,智能流水!$B$2:$B$1001,0)),"")) | L11: =IF($B11="","",IFERROR(INDEX(智能流水!$L$2:$L$1001,MATCH($B11,智能流水!$B$2:$B$1001,0)),"")) | M11: =IF($B11="","",IFERROR(INDEX(智能流水!$M$2:$M$1001,MATCH($B11,智能流水!$B$2:$B$1001,0)),"")) | N11: =IF($B11="","",IFERROR(INDEX(智能流水!$N$2:$N$1001,MATCH($B11,智能流水!$B$2:$B$1001,0)),"")) | O11: =IF($B11="","",IFERROR(INDEX(智能流水!$O$2:$O$1001,MATCH($B11,智能流水!$B$2:$B$1001,0)),""))
A12: =IF($B12="","",11) | B12: =IFERROR(LARGE(智能流水!$B$2:$B$1001,11),"") | C12: =IF($B12="","",IFERROR(INDEX(智能流水!$C$2:$C$1001,MATCH($B12,智能流水!$B$2:$B$1001,0)),"")) | D12: =IF($B12="","",IFERROR(INDEX(智能流水!$D$2:$D$1001,MATCH($B12,智能流水!$B$2:$B$1001,0)),"")) | E12: =IF($B12="","",IFERROR(INDEX(智能流水!$E$2:$E$1001,MATCH($B12,智能流水!$B$2:$B$1001,0)),"")) | F12: =IF($B12="","",IFERROR(INDEX(智能流水!$F$2:$F$1001,MATCH($B12,智能流水!$B$2:$B$1001,0)),"")) | G12: =IF($B12="","",IFERROR(INDEX(智能流水!$G$2:$G$1001,MATCH($B12,智能流水!$B$2:$B$1001,0)),"")) | H12: =IF($B12="","",IFERROR(INDEX(智能流水!$H$2:$H$1001,MATCH($B12,智能流水!$B$2:$B$1001,0)),"")) | I12: =IF($B12="","",IFERROR(INDEX(智能流水!$I$2:$I$1001,MATCH($B12,智能流水!$B$2:$B$1001,0)),"")) | J12: =IF($B12="","",IFERROR(INDEX(智能流水!$J$2:$J$1001,MATCH($B12,智能流水!$B$2:$B$1001,0)),"")) | K12: =IF($B12="","",IFERROR(INDEX(智能流水!$K$2:$K$1001,MATCH($B12,智能流水!$B$2:$B$1001,0)),"")) | L12: =IF($B12="","",IFERROR(INDEX(智能流水!$L$2:$L$1001,MATCH($B12,智能流水!$B$2:$B$1001,0)),"")) | M12: =IF($B12="","",IFERROR(INDEX(智能流水!$M$2:$M$1001,MATCH($B12,智能流水!$B$2:$B$1001,0)),"")) | N12: =IF($B12="","",IFERROR(INDEX(智能流水!$N$2:$N$1001,MATCH($B12,智能流水!$B$2:$B$1001,0)),"")) | O12: =IF($B12="","",IFERROR(INDEX(智能流水!$O$2:$O$1001,MATCH($B12,智能流水!$B$2:$B$1001,0)),""))
A13: =IF($B13="","",12) | B13: =IFERROR(LARGE(智能流水!$B$2:$B$1001,12),"") | C13: =IF($B13="","",IFERROR(INDEX(智能流水!$C$2:$C$1001,MATCH($B13,智能流水!$B$2:$B$1001,0)),"")) | D13: =IF($B13="","",IFERROR(INDEX(智能流水!$D$2:$D$1001,MATCH($B13,智能流水!$B$2:$B$1001,0)),"")) | E13: =IF($B13="","",IFERROR(INDEX(智能流水!$E$2:$E$1001,MATCH($B13,智能流水!$B$2:$B$1001,0)),"")) | F13: =IF($B13="","",IFERROR(INDEX(智能流水!$F$2:$F$1001,MATCH($B13,智能流水!$B$2:$B$1001,0)),"")) | G13: =IF($B13="","",IFERROR(INDEX(智能流水!$G$2:$G$1001,MATCH($B13,智能流水!$B$2:$B$1001,0)),"")) | H13: =IF($B13="","",IFERROR(INDEX(智能流水!$H$2:$H$1001,MATCH($B13,智能流水!$B$2:$B$1001,0)),"")) | I13: =IF($B13="","",IFERROR(INDEX(智能流水!$I$2:$I$1001,MATCH($B13,智能流水!$B$2:$B$1001,0)),"")) | J13: =IF($B13="","",IFERROR(INDEX(智能流水!$J$2:$J$1001,MATCH($B13,智能流水!$B$2:$B$1001,0)),"")) | K13: =IF($B13="","",IFERROR(INDEX(智能流水!$K$2:$K$1001,MATCH($B13,智能流水!$B$2:$B$1001,0)),"")) | L13: =IF($B13="","",IFERROR(INDEX(智能流水!$L$2:$L$1001,MATCH($B13,智能流水!$B$2:$B$1001,0)),"")) | M13: =IF($B13="","",IFERROR(INDEX(智能流水!$M$2:$M$1001,MATCH($B13,智能流水!$B$2:$B$1001,0)),"")) | N13: =IF($B13="","",IFERROR(INDEX(智能流水!$N$2:$N$1001,MATCH($B13,智能流水!$B$2:$B$1001,0)),"")) | O13: =IF($B13="","",IFERROR(INDEX(智能流水!$O$2:$O$1001,MATCH($B13,智能流水!$B$2:$B$1001,0)),""))
A14: =IF($B14="","",13) | B14: =IFERROR(LARGE(智能流水!$B$2:$B$1001,13),"") | C14: =IF($B14="","",IFERROR(INDEX(智能流水!$C$2:$C$1001,MATCH($B14,智能流水!$B$2:$B$1001,0)),"")) | D14: =IF($B14="","",IFERROR(INDEX(智能流水!$D$2:$D$1001,MATCH($B14,智能流水!$B$2:$B$1001,0)),"")) | E14: =IF($B14="","",IFERROR(INDEX(智能流水!$E$2:$E$1001,MATCH($B14,智能流水!$B$2:$B$1001,0)),"")) | F14: =IF($B14="","",IFERROR(INDEX(智能流水!$F$2:$F$1001,MATCH($B14,智能流水!$B$2:$B$1001,0)),"")) | G14: =IF($B14="","",IFERROR(INDEX(智能流水!$G$2:$G$1001,MATCH($B14,智能流水!$B$2:$B$1001,0)),"")) | H14: =IF($B14="","",IFERROR(INDEX(智能流水!$H$2:$H$1001,MATCH($B14,智能流水!$B$2:$B$1001,0)),"")) | I14: =IF($B14="","",IFERROR(INDEX(智能流水!$I$2:$I$1001,MATCH($B14,智能流水!$B$2:$B$1001,0)),"")) | J14: =IF($B14="","",IFERROR(INDEX(智能流水!$J$2:$J$1001,MATCH($B14,智能流水!$B$2:$B$1001,0)),"")) | K14: =IF($B14="","",IFERROR(INDEX(智能流水!$K$2:$K$1001,MATCH($B14,智能流水!$B$2:$B$1001,0)),"")) | L14: =IF($B14="","",IFERROR(INDEX(智能流水!$L$2:$L$1001,MATCH($B14,智能流水!$B$2:$B$1001,0)),"")) | M14: =IF($B14="","",IFERROR(INDEX(智能流水!$M$2:$M$1001,MATCH($B14,智能流水!$B$2:$B$1001,0)),"")) | N14: =IF($B14="","",IFERROR(INDEX(智能流水!$N$2:$N$1001,MATCH($B14,智能流水!$B$2:$B$1001,0)),"")) | O14: =IF($B14="","",IFERROR(INDEX(智能流水!$O$2:$O$1001,MATCH($B14,智能流水!$B$2:$B$1001,0)),""))
A15: =IF($B15="","",14) | B15: =IFERROR(LARGE(智能流水!$B$2:$B$1001,14),"") | C15: =IF($B15="","",IFERROR(INDEX(智能流水!$C$2:$C$1001,MATCH($B15,智能流水!$B$2:$B$1001,0)),"")) | D15: =IF($B15="","",IFERROR(INDEX(智能流水!$D$2:$D$1001,MATCH($B15,智能流水!$B$2:$B$1001,0)),"")) | E15: =IF($B15="","",IFERROR(INDEX(智能流水!$E$2:$E$1001,MATCH($B15,智能流水!$B$2:$B$1001,0)),"")) | F15: =IF($B15="","",IFERROR(INDEX(智能流水!$F$2:$F$1001,MATCH($B15,智能流水!$B$2:$B$1001,0)),"")) | G15: =IF($B15="","",IFERROR(INDEX(智能流水!$G$2:$G$1001,MATCH($B15,智能流水!$B$2:$B$1001,0)),"")) | H15: =IF($B15="","",IFERROR(INDEX(智能流水!$H$2:$H$1001,MATCH($B15,智能流水!$B$2:$B$1001,0)),"")) | I15: =IF($B15="","",IFERROR(INDEX(智能流水!$I$2:$I$1001,MATCH($B15,智能流水!$B$2:$B$1001,0)),"")) | J15: =IF($B15="","",IFERROR(INDEX(智能流水!$J$2:$J$1001,MATCH($B15,智能流水!$B$2:$B$1001,0)),"")) | K15: =IF($B15="","",IFERROR(INDEX(智能流水!$K$2:$K$1001,MATCH($B15,智能流水!$B$2:$B$1001,0)),"")) | L15: =IF($B15="","",IFERROR(INDEX(智能流水!$L$2:$L$1001,MATCH($B15,智能流水!$B$2:$B$1001,0)),"")) | M15: =IF($B15="","",IFERROR(INDEX(智能流水!$M$2:$M$1001,MATCH($B15,智能流水!$B$2:$B$1001,0)),"")) | N15: =IF($B15="","",IFERROR(INDEX(智能流水!$N$2:$N$1001,MATCH($B15,智能流水!$B$2:$B$1001,0)),"")) | O15: =IF($B15="","",IFERROR(INDEX(智能流水!$O$2:$O$1001,MATCH($B15,智能流水!$B$2:$B$1001,0)),""))
A16: =IF($B16="","",15) | B16: =IFERROR(LARGE(智能流水!$B$2:$B$1001,15),"") | C16: =IF($B16="","",IFERROR(INDEX(智能流水!$C$2:$C$1001,MATCH($B16,智能流水!$B$2:$B$1001,0)),"")) | D16: =IF($B16="","",IFERROR(INDEX(智能流水!$D$2:$D$1001,MATCH($B16,智能流水!$B$2:$B$1001,0)),"")) | E16: =IF($B16="","",IFERROR(INDEX(智能流水!$E$2:$E$1001,MATCH($B16,智能流水!$B$2:$B$1001,0)),"")) | F16: =IF($B16="","",IFERROR(INDEX(智能流水!$F$2:$F$1001,MATCH($B16,智能流水!$B$2:$B$1001,0)),"")) | G16: =IF($B16="","",IFERROR(INDEX(智能流水!$G$2:$G$1001,MATCH($B16,智能流水!$B$2:$B$1001,0)),"")) | H16: =IF($B16="","",IFERROR(INDEX(智能流水!$H$2:$H$1001,MATCH($B16,智能流水!$B$2:$B$1001,0)),"")) | I16: =IF($B16="","",IFERROR(INDEX(智能流水!$I$2:$I$1001,MATCH($B16,智能流水!$B$2:$B$1001,0)),"")) | J16: =IF($B16="","",IFERROR(INDEX(智能流水!$J$2:$J$1001,MATCH($B16,智能流水!$B$2:$B$1001,0)),"")) | K16: =IF($B16="","",IFERROR(INDEX(智能流水!$K$2:$K$1001,MATCH($B16,智能流水!$B$2:$B$1001,0)),"")) | L16: =IF($B16="","",IFERROR(INDEX(智能流水!$L$2:$L$1001,MATCH($B16,智能流水!$B$2:$B$1001,0)),"")) | M16: =IF($B16="","",IFERROR(INDEX(智能流水!$M$2:$M$1001,MATCH($B16,智能流水!$B$2:$B$1001,0)),"")) | N16: =IF($B16="","",IFERROR(INDEX(智能流水!$N$2:$N$1001,MATCH($B16,智能流水!$B$2:$B$1001,0)),"")) | O16: =IF($B16="","",IFERROR(INDEX(智能流水!$O$2:$O$1001,MATCH($B16,智能流水!$B$2:$B$1001,0)),""))
A17: =IF($B17="","",16) | B17: =IFERROR(LARGE(智能流水!$B$2:$B$1001,16),"") | C17: =IF($B17="","",IFERROR(INDEX(智能流水!$C$2:$C$1001,MATCH($B17,智能流水!$B$2:$B$1001,0)),"")) | D17: =IF($B17="","",IFERROR(INDEX(智能流水!$D$2:$D$1001,MATCH($B17,智能流水!$B$2:$B$1001,0)),"")) | E17: =IF($B17="","",IFERROR(INDEX(智能流水!$E$2:$E$1001,MATCH($B17,智能流水!$B$2:$B$1001,0)),"")) | F17: =IF($B17="","",IFERROR(INDEX(智能流水!$F$2:$F$1001,MATCH($B17,智能流水!$B$2:$B$1001,0)),"")) | G17: =IF($B17="","",IFERROR(INDEX(智能流水!$G$2:$G$1001,MATCH($B17,智能流水!$B$2:$B$1001,0)),"")) | H17: =IF($B17="","",IFERROR(INDEX(智能流水!$H$2:$H$1001,MATCH($B17,智能流水!$B$2:$B$1001,0)),"")) | I17: =IF($B17="","",IFERROR(INDEX(智能流水!$I$2:$I$1001,MATCH($B17,智能流水!$B$2:$B$1001,0)),"")) | J17: =IF($B17="","",IFERROR(INDEX(智能流水!$J$2:$J$1001,MATCH($B17,智能流水!$B$2:$B$1001,0)),"")) | K17: =IF($B17="","",IFERROR(INDEX(智能流水!$K$2:$K$1001,MATCH($B17,智能流水!$B$2:$B$1001,0)),"")) | L17: =IF($B17="","",IFERROR(INDEX(智能流水!$L$2:$L$1001,MATCH($B17,智能流水!$B$2:$B$1001,0)),"")) | M17: =IF($B17="","",IFERROR(INDEX(智能流水!$M$2:$M$1001,MATCH($B17,智能流水!$B$2:$B$1001,0)),"")) | N17: =IF($B17="","",IFERROR(INDEX(智能流水!$N$2:$N$1001,MATCH($B17,智能流水!$B$2:$B$1001,0)),"")) | O17: =IF($B17="","",IFERROR(INDEX(智能流水!$O$2:$O$1001,MATCH($B17,智能流水!$B$2:$B$1001,0)),""))
A18: =IF($B18="","",17) | B18: =IFERROR(LARGE(智能流水!$B$2:$B$1001,17),"") | C18: =IF($B18="","",IFERROR(INDEX(智能流水!$C$2:$C$1001,MATCH($B18,智能流水!$B$2:$B$1001,0)),"")) | D18: =IF($B18="","",IFERROR(INDEX(智能流水!$D$2:$D$1001,MATCH($B18,智能流水!$B$2:$B$1001,0)),"")) | E18: =IF($B18="","",IFERROR(INDEX(智能流水!$E$2:$E$1001,MATCH($B18,智能流水!$B$2:$B$1001,0)),"")) | F18: =IF($B18="","",IFERROR(INDEX(智能流水!$F$2:$F$1001,MATCH($B18,智能流水!$B$2:$B$1001,0)),"")) | G18: =IF($B18="","",IFERROR(INDEX(智能流水!$G$2:$G$1001,MATCH($B18,智能流水!$B$2:$B$1001,0)),"")) | H18: =IF($B18="","",IFERROR(INDEX(智能流水!$H$2:$H$1001,MATCH($B18,智能流水!$B$2:$B$1001,0)),"")) | I18: =IF($B18="","",IFERROR(INDEX(智能流水!$I$2:$I$1001,MATCH($B18,智能流水!$B$2:$B$1001,0)),"")) | J18: =IF($B18="","",IFERROR(INDEX(智能流水!$J$2:$J$1001,MATCH($B18,智能流水!$B$2:$B$1001,0)),"")) | K18: =IF($B18="","",IFERROR(INDEX(智能流水!$K$2:$K$1001,MATCH($B18,智能流水!$B$2:$B$1001,0)),"")) | L18: =IF($B18="","",IFERROR(INDEX(智能流水!$L$2:$L$1001,MATCH($B18,智能流水!$B$2:$B$1001,0)),"")) | M18: =IF($B18="","",IFERROR(INDEX(智能流水!$M$2:$M$1001,MATCH($B18,智能流水!$B$2:$B$1001,0)),"")) | N18: =IF($B18="","",IFERROR(INDEX(智能流水!$N$2:$N$1001,MATCH($B18,智能流水!$B$2:$B$1001,0)),"")) | O18: =IF($B18="","",IFERROR(INDEX(智能流水!$O$2:$O$1001,MATCH($B18,智能流水!$B$2:$B$1001,0)),""))
A19: =IF($B19="","",18) | B19: =IFERROR(LARGE(智能流水!$B$2:$B$1001,18),"") | C19: =IF($B19="","",IFERROR(INDEX(智能流水!$C$2:$C$1001,MATCH($B19,智能流水!$B$2:$B$1001,0)),"")) | D19: =IF($B19="","",IFERROR(INDEX(智能流水!$D$2:$D$1001,MATCH($B19,智能流水!$B$2:$B$1001,0)),"")) | E19: =IF($B19="","",IFERROR(INDEX(智能流水!$E$2:$E$1001,MATCH($B19,智能流水!$B$2:$B$1001,0)),"")) | F19: =IF($B19="","",IFERROR(INDEX(智能流水!$F$2:$F$1001,MATCH($B19,智能流水!$B$2:$B$1001,0)),"")) | G19: =IF($B19="","",IFERROR(INDEX(智能流水!$G$2:$G$1001,MATCH($B19,智能流水!$B$2:$B$1001,0)),"")) | H19: =IF($B19="","",IFERROR(INDEX(智能流水!$H$2:$H$1001,MATCH($B19,智能流水!$B$2:$B$1001,0)),"")) | I19: =IF($B19="","",IFERROR(INDEX(智能流水!$I$2:$I$1001,MATCH($B19,智能流水!$B$2:$B$1001,0)),"")) | J19: =IF($B19="","",IFERROR(INDEX(智能流水!$J$2:$J$1001,MATCH($B19,智能流水!$B$2:$B$1001,0)),"")) | K19: =IF($B19="","",IFERROR(INDEX(智能流水!$K$2:$K$1001,MATCH($B19,智能流水!$B$2:$B$1001,0)),"")) | L19: =IF($B19="","",IFERROR(INDEX(智能流水!$L$2:$L$1001,MATCH($B19,智能流水!$B$2:$B$1001,0)),"")) | M19: =IF($B19="","",IFERROR(INDEX(智能流水!$M$2:$M$1001,MATCH($B19,智能流水!$B$2:$B$1001,0)),"")) | N19: =IF($B19="","",IFERROR(INDEX(智能流水!$N$2:$N$1001,MATCH($B19,智能流水!$B$2:$B$1001,0)),"")) | O19: =IF($B19="","",IFERROR(INDEX(智能流水!$O$2:$O$1001,MATCH($B19,智能流水!$B$2:$B$1001,0)),""))
A20: =IF($B20="","",19) | B20: =IFERROR(LARGE(智能流水!$B$2:$B$1001,19),"") | C20: =IF($B20="","",IFERROR(INDEX(智能流水!$C$2:$C$1001,MATCH($B20,智能流水!$B$2:$B$1001,0)),"")) | D20: =IF($B20="","",IFERROR(INDEX(智能流水!$D$2:$D$1001,MATCH($B20,智能流水!$B$2:$B$1001,0)),"")) | E20: =IF($B20="","",IFERROR(INDEX(智能流水!$E$2:$E$1001,MATCH($B20,智能流水!$B$2:$B$1001,0)),"")) | F20: =IF($B20="","",IFERROR(INDEX(智能流水!$F$2:$F$1001,MATCH($B20,智能流水!$B$2:$B$1001,0)),"")) | G20: =IF($B20="","",IFERROR(INDEX(智能流水!$G$2:$G$1001,MATCH($B20,智能流水!$B$2:$B$1001,0)),"")) | H20: =IF($B20="","",IFERROR(INDEX(智能流水!$H$2:$H$1001,MATCH($B20,智能流水!$B$2:$B$1001,0)),"")) | I20: =IF($B20="","",IFERROR(INDEX(智能流水!$I$2:$I$1001,MATCH($B20,智能流水!$B$2:$B$1001,0)),"")) | J20: =IF($B20="","",IFERROR(INDEX(智能流水!$J$2:$J$1001,MATCH($B20,智能流水!$B$2:$B$1001,0)),"")) | K20: =IF($B20="","",IFERROR(INDEX(智能流水!$K$2:$K$1001,MATCH($B20,智能流水!$B$2:$B$1001,0)),"")) | L20: =IF($B20="","",IFERROR(INDEX(智能流水!$L$2:$L$1001,MATCH($B20,智能流水!$B$2:$B$1001,0)),"")) | M20: =IF($B20="","",IFERROR(INDEX(智能流水!$M$2:$M$1001,MATCH($B20,智能流水!$B$2:$B$1001,0)),"")) | N20: =IF($B20="","",IFERROR(INDEX(智能流水!$N$2:$N$1001,MATCH($B20,智能流水!$B$2:$B$1001,0)),"")) | O20: =IF($B20="","",IFERROR(INDEX(智能流水!$O$2:$O$1001,MATCH($B20,智能流水!$B$2:$B$1001,0)),""))
A21: =IF($B21="","",20) | B21: =IFERROR(LARGE(智能流水!$B$2:$B$1001,20),"") | C21: =IF($B21="","",IFERROR(INDEX(智能流水!$C$2:$C$1001,MATCH($B21,智能流水!$B$2:$B$1001,0)),"")) | D21: =IF($B21="","",IFERROR(INDEX(智能流水!$D$2:$D$1001,MATCH($B21,智能流水!$B$2:$B$1001,0)),"")) | E21: =IF($B21="","",IFERROR(INDEX(智能流水!$E$2:$E$1001,MATCH($B21,智能流水!$B$2:$B$1001,0)),"")) | F21: =IF($B21="","",IFERROR(INDEX(智能流水!$F$2:$F$1001,MATCH($B21,智能流水!$B$2:$B$1001,0)),"")) | G21: =IF($B21="","",IFERROR(INDEX(智能流水!$G$2:$G$1001,MATCH($B21,智能流水!$B$2:$B$1001,0)),"")) | H21: =IF($B21="","",IFERROR(INDEX(智能流水!$H$2:$H$1001,MATCH($B21,智能流水!$B$2:$B$1001,0)),"")) | I21: =IF($B21="","",IFERROR(INDEX(智能流水!$I$2:$I$1001,MATCH($B21,智能流水!$B$2:$B$1001,0)),"")) | J21: =IF($B21="","",IFERROR(INDEX(智能流水!$J$2:$J$1001,MATCH($B21,智能流水!$B$2:$B$1001,0)),"")) | K21: =IF($B21="","",IFERROR(INDEX(智能流水!$K$2:$K$1001,MATCH($B21,智能流水!$B$2:$B$1001,0)),"")) | L21: =IF($B21="","",IFERROR(INDEX(智能流水!$L$2:$L$1001,MATCH($B21,智能流水!$B$2:$B$1001,0)),"")) | M21: =IF($B21="","",IFERROR(INDEX(智能流水!$M$2:$M$1001,MATCH($B21,智能流水!$B$2:$B$1001,0)),"")) | N21: =IF($B21="","",IFERROR(INDEX(智能流水!$N$2:$N$1001,MATCH($B21,智能流水!$B$2:$B$1001,0)),"")) | O21: =IF($B21="","",IFERROR(INDEX(智能流水!$O$2:$O$1001,MATCH($B21,智能流水!$B$2:$B$1001,0)),""))
A22: =IF($B22="","",21) | B22: =IFERROR(LARGE(智能流水!$B$2:$B$1001,21),"") | C22: =IF($B22="","",IFERROR(INDEX(智能流水!$C$2:$C$1001,MATCH($B22,智能流水!$B$2:$B$1001,0)),"")) | D22: =IF($B22="","",IFERROR(INDEX(智能流水!$D$2:$D$1001,MATCH($B22,智能流水!$B$2:$B$1001,0)),"")) | E22: =IF($B22="","",IFERROR(INDEX(智能流水!$E$2:$E$1001,MATCH($B22,智能流水!$B$2:$B$1001,0)),"")) | F22: =IF($B22="","",IFERROR(INDEX(智能流水!$F$2:$F$1001,MATCH($B22,智能流水!$B$2:$B$1001,0)),"")) | G22: =IF($B22="","",IFERROR(INDEX(智能流水!$G$2:$G$1001,MATCH($B22,智能流水!$B$2:$B$1001,0)),"")) | H22: =IF($B22="","",IFERROR(INDEX(智能流水!$H$2:$H$1001,MATCH($B22,智能流水!$B$2:$B$1001,0)),"")) | I22: =IF($B22="","",IFERROR(INDEX(智能流水!$I$2:$I$1001,MATCH($B22,智能流水!$B$2:$B$1001,0)),"")) | J22: =IF($B22="","",IFERROR(INDEX(智能流水!$J$2:$J$1001,MATCH($B22,智能流水!$B$2:$B$1001,0)),"")) | K22: =IF($B22="","",IFERROR(INDEX(智能流水!$K$2:$K$1001,MATCH($B22,智能流水!$B$2:$B$1001,0)),"")) | L22: =IF($B22="","",IFERROR(INDEX(智能流水!$L$2:$L$1001,MATCH($B22,智能流水!$B$2:$B$1001,0)),"")) | M22: =IF($B22="","",IFERROR(INDEX(智能流水!$M$2:$M$1001,MATCH($B22,智能流水!$B$2:$B$1001,0)),"")) | N22: =IF($B22="","",IFERROR(INDEX(智能流水!$N$2:$N$1001,MATCH($B22,智能流水!$B$2:$B$1001,0)),"")) | O22: =IF($B22="","",IFERROR(INDEX(智能流水!$O$2:$O$1001,MATCH($B22,智能流水!$B$2:$B$1001,0)),""))
A23: =IF($B23="","",22) | B23: =IFERROR(LARGE(智能流水!$B$2:$B$1001,22),"") | C23: =IF($B23="","",IFERROR(INDEX(智能流水!$C$2:$C$1001,MATCH($B23,智能流水!$B$2:$B$1001,0)),"")) | D23: =IF($B23="","",IFERROR(INDEX(智能流水!$D$2:$D$1001,MATCH($B23,智能流水!$B$2:$B$1001,0)),"")) | E23: =IF($B23="","",IFERROR(INDEX(智能流水!$E$2:$E$1001,MATCH($B23,智能流水!$B$2:$B$1001,0)),"")) | F23: =IF($B23="","",IFERROR(INDEX(智能流水!$F$2:$F$1001,MATCH($B23,智能流水!$B$2:$B$1001,0)),"")) | G23: =IF($B23="","",IFERROR(INDEX(智能流水!$G$2:$G$1001,MATCH($B23,智能流水!$B$2:$B$1001,0)),"")) | H23: =IF($B23="","",IFERROR(INDEX(智能流水!$H$2:$H$1001,MATCH($B23,智能流水!$B$2:$B$1001,0)),"")) | I23: =IF($B23="","",IFERROR(INDEX(智能流水!$I$2:$I$1001,MATCH($B23,智能流水!$B$2:$B$1001,0)),"")) | J23: =IF($B23="","",IFERROR(INDEX(智能流水!$J$2:$J$1001,MATCH($B23,智能流水!$B$2:$B$1001,0)),"")) | K23: =IF($B23="","",IFERROR(INDEX(智能流水!$K$2:$K$1001,MATCH($B23,智能流水!$B$2:$B$1001,0)),"")) | L23: =IF($B23="","",IFERROR(INDEX(智能流水!$L$2:$L$1001,MATCH($B23,智能流水!$B$2:$B$1001,0)),"")) | M23: =IF($B23="","",IFERROR(INDEX(智能流水!$M$2:$M$1001,MATCH($B23,智能流水!$B$2:$B$1001,0)),"")) | N23: =IF($B23="","",IFERROR(INDEX(智能流水!$N$2:$N$1001,MATCH($B23,智能流水!$B$2:$B$1001,0)),"")) | O23: =IF($B23="","",IFERROR(INDEX(智能流水!$O$2:$O$1001,MATCH($B23,智能流水!$B$2:$B$1001,0)),""))
A24: =IF($B24="","",23) | B24: =IFERROR(LARGE(智能流水!$B$2:$B$1001,23),"") | C24: =IF($B24="","",IFERROR(INDEX(智能流水!$C$2:$C$1001,MATCH($B24,智能流水!$B$2:$B$1001,0)),"")) | D24: =IF($B24="","",IFERROR(INDEX(智能流水!$D$2:$D$1001,MATCH($B24,智能流水!$B$2:$B$1001,0)),"")) | E24: =IF($B24="","",IFERROR(INDEX(智能流水!$E$2:$E$1001,MATCH($B24,智能流水!$B$2:$B$1001,0)),"")) | F24: =IF($B24="","",IFERROR(INDEX(智能流水!$F$2:$F$1001,MATCH($B24,智能流水!$B$2:$B$1001,0)),"")) | G24: =IF($B24="","",IFERROR(INDEX(智能流水!$G$2:$G$1001,MATCH($B24,智能流水!$B$2:$B$1001,0)),"")) | H24: =IF($B24="","",IFERROR(INDEX(智能流水!$H$2:$H$1001,MATCH($B24,智能流水!$B$2:$B$1001,0)),"")) | I24: =IF($B24="","",IFERROR(INDEX(智能流水!$I$2:$I$1001,MATCH($B24,智能流水!$B$2:$B$1001,0)),"")) | J24: =IF($B24="","",IFERROR(INDEX(智能流水!$J$2:$J$1001,MATCH($B24,智能流水!$B$2:$B$1001,0)),"")) | K24: =IF($B24="","",IFERROR(INDEX(智能流水!$K$2:$K$1001,MATCH($B24,智能流水!$B$2:$B$1001,0)),"")) | L24: =IF($B24="","",IFERROR(INDEX(智能流水!$L$2:$L$1001,MATCH($B24,智能流水!$B$2:$B$1001,0)),"")) | M24: =IF($B24="","",IFERROR(INDEX(智能流水!$M$2:$M$1001,MATCH($B24,智能流水!$B$2:$B$1001,0)),"")) | N24: =IF($B24="","",IFERROR(INDEX(智能流水!$N$2:$N$1001,MATCH($B24,智能流水!$B$2:$B$1001,0)),"")) | O24: =IF($B24="","",IFERROR(INDEX(智能流水!$O$2:$O$1001,MATCH($B24,智能流水!$B$2:$B$1001,0)),""))
A25: =IF($B25="","",24) | B25: =IFERROR(LARGE(智能流水!$B$2:$B$1001,24),"") | C25: =IF($B25="","",IFERROR(INDEX(智能流水!$C$2:$C$1001,MATCH($B25,智能流水!$B$2:$B$1001,0)),"")) | D25: =IF($B25="","",IFERROR(INDEX(智能流水!$D$2:$D$1001,MATCH($B25,智能流水!$B$2:$B$1001,0)),"")) | E25: =IF($B25="","",IFERROR(INDEX(智能流水!$E$2:$E$1001,MATCH($B25,智能流水!$B$2:$B$1001,0)),"")) | F25: =IF($B25="","",IFERROR(INDEX(智能流水!$F$2:$F$1001,MATCH($B25,智能流水!$B$2:$B$1001,0)),"")) | G25: =IF($B25="","",IFERROR(INDEX(智能流水!$G$2:$G$1001,MATCH($B25,智能流水!$B$2:$B$1001,0)),"")) | H25: =IF($B25="","",IFERROR(INDEX(智能流水!$H$2:$H$1001,MATCH($B25,智能流水!$B$2:$B$1001,0)),"")) | I25: =IF($B25="","",IFERROR(INDEX(智能流水!$I$2:$I$1001,MATCH($B25,智能流水!$B$2:$B$1001,0)),"")) | J25: =IF($B25="","",IFERROR(INDEX(智能流水!$J$2:$J$1001,MATCH($B25,智能流水!$B$2:$B$1001,0)),"")) | K25: =IF($B25="","",IFERROR(INDEX(智能流水!$K$2:$K$1001,MATCH($B25,智能流水!$B$2:$B$1001,0)),"")) | L25: =IF($B25="","",IFERROR(INDEX(智能流水!$L$2:$L$1001,MATCH($B25,智能流水!$B$2:$B$1001,0)),"")) | M25: =IF($B25="","",IFERROR(INDEX(智能流水!$M$2:$M$1001,MATCH($B25,智能流水!$B$2:$B$1001,0)),"")) | N25: =IF($B25="","",IFERROR(INDEX(智能流水!$N$2:$N$1001,MATCH($B25,智能流水!$B$2:$B$1001,0)),"")) | O25: =IF($B25="","",IFERROR(INDEX(智能流水!$O$2:$O$1001,MATCH($B25,智能流水!$B$2:$B$1001,0)),""))
A26: =IF($B26="","",25) | B26: =IFERROR(LARGE(智能流水!$B$2:$B$1001,25),"") | C26: =IF($B26="","",IFERROR(INDEX(智能流水!$C$2:$C$1001,MATCH($B26,智能流水!$B$2:$B$1001,0)),"")) | D26: =IF($B26="","",IFERROR(INDEX(智能流水!$D$2:$D$1001,MATCH($B26,智能流水!$B$2:$B$1001,0)),"")) | E26: =IF($B26="","",IFERROR(INDEX(智能流水!$E$2:$E$1001,MATCH($B26,智能流水!$B$2:$B$1001,0)),"")) | F26: =IF($B26="","",IFERROR(INDEX(智能流水!$F$2:$F$1001,MATCH($B26,智能流水!$B$2:$B$1001,0)),"")) | G26: =IF($B26="","",IFERROR(INDEX(智能流水!$G$2:$G$1001,MATCH($B26,智能流水!$B$2:$B$1001,0)),"")) | H26: =IF($B26="","",IFERROR(INDEX(智能流水!$H$2:$H$1001,MATCH($B26,智能流水!$B$2:$B$1001,0)),"")) | I26: =IF($B26="","",IFERROR(INDEX(智能流水!$I$2:$I$1001,MATCH($B26,智能流水!$B$2:$B$1001,0)),"")) | J26: =IF($B26="","",IFERROR(INDEX(智能流水!$J$2:$J$1001,MATCH($B26,智能流水!$B$2:$B$1001,0)),"")) | K26: =IF($B26="","",IFERROR(INDEX(智能流水!$K$2:$K$1001,MATCH($B26,智能流水!$B$2:$B$1001,0)),"")) | L26: =IF($B26="","",IFERROR(INDEX(智能流水!$L$2:$L$1001,MATCH($B26,智能流水!$B$2:$B$1001,0)),"")) | M26: =IF($B26="","",IFERROR(INDEX(智能流水!$M$2:$M$1001,MATCH($B26,智能流水!$B$2:$B$1001,0)),"")) | N26: =IF($B26="","",IFERROR(INDEX(智能流水!$N$2:$N$1001,MATCH($B26,智能流水!$B$2:$B$1001,0)),"")) | O26: =IF($B26="","",IFERROR(INDEX(智能流水!$O$2:$O$1001,MATCH($B26,智能流水!$B$2:$B$1001,0)),""))
A27: =IF($B27="","",26) | B27: =IFERROR(LARGE(智能流水!$B$2:$B$1001,26),"") | C27: =IF($B27="","",IFERROR(INDEX(智能流水!$C$2:$C$1001,MATCH($B27,智能流水!$B$2:$B$1001,0)),"")) | D27: =IF($B27="","",IFERROR(INDEX(智能流水!$D$2:$D$1001,MATCH($B27,智能流水!$B$2:$B$1001,0)),"")) | E27: =IF($B27="","",IFERROR(INDEX(智能流水!$E$2:$E$1001,MATCH($B27,智能流水!$B$2:$B$1001,0)),"")) | F27: =IF($B27="","",IFERROR(INDEX(智能流水!$F$2:$F$1001,MATCH($B27,智能流水!$B$2:$B$1001,0)),"")) | G27: =IF($B27="","",IFERROR(INDEX(智能流水!$G$2:$G$1001,MATCH($B27,智能流水!$B$2:$B$1001,0)),"")) | H27: =IF($B27="","",IFERROR(INDEX(智能流水!$H$2:$H$1001,MATCH($B27,智能流水!$B$2:$B$1001,0)),"")) | I27: =IF($B27="","",IFERROR(INDEX(智能流水!$I$2:$I$1001,MATCH($B27,智能流水!$B$2:$B$1001,0)),"")) | J27: =IF($B27="","",IFERROR(INDEX(智能流水!$J$2:$J$1001,MATCH($B27,智能流水!$B$2:$B$1001,0)),"")) | K27: =IF($B27="","",IFERROR(INDEX(智能流水!$K$2:$K$1001,MATCH($B27,智能流水!$B$2:$B$1001,0)),"")) | L27: =IF($B27="","",IFERROR(INDEX(智能流水!$L$2:$L$1001,MATCH($B27,智能流水!$B$2:$B$1001,0)),"")) | M27: =IF($B27="","",IFERROR(INDEX(智能流水!$M$2:$M$1001,MATCH($B27,智能流水!$B$2:$B$1001,0)),"")) | N27: =IF($B27="","",IFERROR(INDEX(智能流水!$N$2:$N$1001,MATCH($B27,智能流水!$B$2:$B$1001,0)),"")) | O27: =IF($B27="","",IFERROR(INDEX(智能流水!$O$2:$O$1001,MATCH($B27,智能流水!$B$2:$B$1001,0)),""))
A28: =IF($B28="","",27) | B28: =IFERROR(LARGE(智能流水!$B$2:$B$1001,27),"") | C28: =IF($B28="","",IFERROR(INDEX(智能流水!$C$2:$C$1001,MATCH($B28,智能流水!$B$2:$B$1001,0)),"")) | D28: =IF($B28="","",IFERROR(INDEX(智能流水!$D$2:$D$1001,MATCH($B28,智能流水!$B$2:$B$1001,0)),"")) | E28: =IF($B28="","",IFERROR(INDEX(智能流水!$E$2:$E$1001,MATCH($B28,智能流水!$B$2:$B$1001,0)),"")) | F28: =IF($B28="","",IFERROR(INDEX(智能流水!$F$2:$F$1001,MATCH($B28,智能流水!$B$2:$B$1001,0)),"")) | G28: =IF($B28="","",IFERROR(INDEX(智能流水!$G$2:$G$1001,MATCH($B28,智能流水!$B$2:$B$1001,0)),"")) | H28: =IF($B28="","",IFERROR(INDEX(智能流水!$H$2:$H$1001,MATCH($B28,智能流水!$B$2:$B$1001,0)),"")) | I28: =IF($B28="","",IFERROR(INDEX(智能流水!$I$2:$I$1001,MATCH($B28,智能流水!$B$2:$B$1001,0)),"")) | J28: =IF($B28="","",IFERROR(INDEX(智能流水!$J$2:$J$1001,MATCH($B28,智能流水!$B$2:$B$1001,0)),"")) | K28: =IF($B28="","",IFERROR(INDEX(智能流水!$K$2:$K$1001,MATCH($B28,智能流水!$B$2:$B$1001,0)),"")) | L28: =IF($B28="","",IFERROR(INDEX(智能流水!$L$2:$L$1001,MATCH($B28,智能流水!$B$2:$B$1001,0)),"")) | M28: =IF($B28="","",IFERROR(INDEX(智能流水!$M$2:$M$1001,MATCH($B28,智能流水!$B$2:$B$1001,0)),"")) | N28: =IF($B28="","",IFERROR(INDEX(智能流水!$N$2:$N$1001,MATCH($B28,智能流水!$B$2:$B$1001,0)),"")) | O28: =IF($B28="","",IFERROR(INDEX(智能流水!$O$2:$O$1001,MATCH($B28,智能流水!$B$2:$B$1001,0)),""))
A29: =IF($B29="","",28) | B29: =IFERROR(LARGE(智能流水!$B$2:$B$1001,28),"") | C29: =IF($B29="","",IFERROR(INDEX(智能流水!$C$2:$C$1001,MATCH($B29,智能流水!$B$2:$B$1001,0)),"")) | D29: =IF($B29="","",IFERROR(INDEX(智能流水!$D$2:$D$1001,MATCH($B29,智能流水!$B$2:$B$1001,0)),"")) | E29: =IF($B29="","",IFERROR(INDEX(智能流水!$E$2:$E$1001,MATCH($B29,智能流水!$B$2:$B$1001,0)),"")) | F29: =IF($B29="","",IFERROR(INDEX(智能流水!$F$2:$F$1001,MATCH($B29,智能流水!$B$2:$B$1001,0)),"")) | G29: =IF($B29="","",IFERROR(INDEX(智能流水!$G$2:$G$1001,MATCH($B29,智能流水!$B$2:$B$1001,0)),"")) | H29: =IF($B29="","",IFERROR(INDEX(智能流水!$H$2:$H$1001,MATCH($B29,智能流水!$B$2:$B$1001,0)),"")) | I29: =IF($B29="","",IFERROR(INDEX(智能流水!$I$2:$I$1001,MATCH($B29,智能流水!$B$2:$B$1001,0)),"")) | J29: =IF($B29="","",IFERROR(INDEX(智能流水!$J$2:$J$1001,MATCH($B29,智能流水!$B$2:$B$1001,0)),"")) | K29: =IF($B29="","",IFERROR(INDEX(智能流水!$K$2:$K$1001,MATCH($B29,智能流水!$B$2:$B$1001,0)),"")) | L29: =IF($B29="","",IFERROR(INDEX(智能流水!$L$2:$L$1001,MATCH($B29,智能流水!$B$2:$B$1001,0)),"")) | M29: =IF($B29="","",IFERROR(INDEX(智能流水!$M$2:$M$1001,MATCH($B29,智能流水!$B$2:$B$1001,0)),"")) | N29: =IF($B29="","",IFERROR(INDEX(智能流水!$N$2:$N$1001,MATCH($B29,智能流水!$B$2:$B$1001,0)),"")) | O29: =IF($B29="","",IFERROR(INDEX(智能流水!$O$2:$O$1001,MATCH($B29,智能流水!$B$2:$B$1001,0)),""))
A30: =IF($B30="","",29) | B30: =IFERROR(LARGE(智能流水!$B$2:$B$1001,29),"") | C30: =IF($B30="","",IFERROR(INDEX(智能流水!$C$2:$C$1001,MATCH($B30,智能流水!$B$2:$B$1001,0)),"")) | D30: =IF($B30="","",IFERROR(INDEX(智能流水!$D$2:$D$1001,MATCH($B30,智能流水!$B$2:$B$1001,0)),"")) | E30: =IF($B30="","",IFERROR(INDEX(智能流水!$E$2:$E$1001,MATCH($B30,智能流水!$B$2:$B$1001,0)),"")) | F30: =IF($B30="","",IFERROR(INDEX(智能流水!$F$2:$F$1001,MATCH($B30,智能流水!$B$2:$B$1001,0)),"")) | G30: =IF($B30="","",IFERROR(INDEX(智能流水!$G$2:$G$1001,MATCH($B30,智能流水!$B$2:$B$1001,0)),"")) | H30: =IF($B30="","",IFERROR(INDEX(智能流水!$H$2:$H$1001,MATCH($B30,智能流水!$B$2:$B$1001,0)),"")) | I30: =IF($B30="","",IFERROR(INDEX(智能流水!$I$2:$I$1001,MATCH($B30,智能流水!$B$2:$B$1001,0)),"")) | J30: =IF($B30="","",IFERROR(INDEX(智能流水!$J$2:$J$1001,MATCH($B30,智能流水!$B$2:$B$1001,0)),"")) | K30: =IF($B30="","",IFERROR(INDEX(智能流水!$K$2:$K$1001,MATCH($B30,智能流水!$B$2:$B$1001,0)),"")) | L30: =IF($B30="","",IFERROR(INDEX(智能流水!$L$2:$L$1001,MATCH($B30,智能流水!$B$2:$B$1001,0)),"")) | M30: =IF($B30="","",IFERROR(INDEX(智能流水!$M$2:$M$1001,MATCH($B30,智能流水!$B$2:$B$1001,0)),"")) | N30: =IF($B30="","",IFERROR(INDEX(智能流水!$N$2:$N$1001,MATCH($B30,智能流水!$B$2:$B$1001,0)),"")) | O30: =IF($B30="","",IFERROR(INDEX(智能流水!$O$2:$O$1001,MATCH($B30,智能流水!$B$2:$B$1001,0)),""))
A31: =IF($B31="","",30) | B31: =IFERROR(LARGE(智能流水!$B$2:$B$1001,30),"") | C31: =IF($B31="","",IFERROR(INDEX(智能流水!$C$2:$C$1001,MATCH($B31,智能流水!$B$2:$B$1001,0)),"")) | D31: =IF($B31="","",IFERROR(INDEX(智能流水!$D$2:$D$1001,MATCH($B31,智能流水!$B$2:$B$1001,0)),"")) | E31: =IF($B31="","",IFERROR(INDEX(智能流水!$E$2:$E$1001,MATCH($B31,智能流水!$B$2:$B$1001,0)),"")) | F31: =IF($B31="","",IFERROR(INDEX(智能流水!$F$2:$F$1001,MATCH($B31,智能流水!$B$2:$B$1001,0)),"")) | G31: =IF($B31="","",IFERROR(INDEX(智能流水!$G$2:$G$1001,MATCH($B31,智能流水!$B$2:$B$1001,0)),"")) | H31: =IF($B31="","",IFERROR(INDEX(智能流水!$H$2:$H$1001,MATCH($B31,智能流水!$B$2:$B$1001,0)),"")) | I31: =IF($B31="","",IFERROR(INDEX(智能流水!$I$2:$I$1001,MATCH($B31,智能流水!$B$2:$B$1001,0)),"")) | J31: =IF($B31="","",IFERROR(INDEX(智能流水!$J$2:$J$1001,MATCH($B31,智能流水!$B$2:$B$1001,0)),"")) | K31: =IF($B31="","",IFERROR(INDEX(智能流水!$K$2:$K$1001,MATCH($B31,智能流水!$B$2:$B$1001,0)),"")) | L31: =IF($B31="","",IFERROR(INDEX(智能流水!$L$2:$L$1001,MATCH($B31,智能流水!$B$2:$B$1001,0)),"")) | M31: =IF($B31="","",IFERROR(INDEX(智能流水!$M$2:$M$1001,MATCH($B31,智能流水!$B$2:$B$1001,0)),"")) | N31: =IF($B31="","",IFERROR(INDEX(智能流水!$N$2:$N$1001,MATCH($B31,智能流水!$B$2:$B$1001,0)),"")) | O31: =IF($B31="","",IFERROR(INDEX(智能流水!$O$2:$O$1001,MATCH($B31,智能流水!$B$2:$B$1001,0)),""))
A32: =IF($B32="","",31) | B32: =IFERROR(LARGE(智能流水!$B$2:$B$1001,31),"") | C32: =IF($B32="","",IFERROR(INDEX(智能流水!$C$2:$C$1001,MATCH($B32,智能流水!$B$2:$B$1001,0)),"")) | D32: =IF($B32="","",IFERROR(INDEX(智能流水!$D$2:$D$1001,MATCH($B32,智能流水!$B$2:$B$1001,0)),"")) | E32: =IF($B32="","",IFERROR(INDEX(智能流水!$E$2:$E$1001,MATCH($B32,智能流水!$B$2:$B$1001,0)),"")) | F32: =IF($B32="","",IFERROR(INDEX(智能流水!$F$2:$F$1001,MATCH($B32,智能流水!$B$2:$B$1001,0)),"")) | G32: =IF($B32="","",IFERROR(INDEX(智能流水!$G$2:$G$1001,MATCH($B32,智能流水!$B$2:$B$1001,0)),"")) | H32: =IF($B32="","",IFERROR(INDEX(智能流水!$H$2:$H$1001,MATCH($B32,智能流水!$B$2:$B$1001,0)),"")) | I32: =IF($B32="","",IFERROR(INDEX(智能流水!$I$2:$I$1001,MATCH($B32,智能流水!$B$2:$B$1001,0)),"")) | J32: =IF($B32="","",IFERROR(INDEX(智能流水!$J$2:$J$1001,MATCH($B32,智能流水!$B$2:$B$1001,0)),"")) | K32: =IF($B32="","",IFERROR(INDEX(智能流水!$K$2:$K$1001,MATCH($B32,智能流水!$B$2:$B$1001,0)),"")) | L32: =IF($B32="","",IFERROR(INDEX(智能流水!$L$2:$L$1001,MATCH($B32,智能流水!$B$2:$B$1001,0)),"")) | M32: =IF($B32="","",IFERROR(INDEX(智能流水!$M$2:$M$1001,MATCH($B32,智能流水!$B$2:$B$1001,0)),"")) | N32: =IF($B32="","",IFERROR(INDEX(智能流水!$N$2:$N$1001,MATCH($B32,智能流水!$B$2:$B$1001,0)),"")) | O32: =IF($B32="","",IFERROR(INDEX(智能流水!$O$2:$O$1001,MATCH($B32,智能流水!$B$2:$B$1001,0)),""))
A33: =IF($B33="","",32) | B33: =IFERROR(LARGE(智能流水!$B$2:$B$1001,32),"") | C33: =IF($B33="","",IFERROR(INDEX(智能流水!$C$2:$C$1001,MATCH($B33,智能流水!$B$2:$B$1001,0)),"")) | D33: =IF($B33="","",IFERROR(INDEX(智能流水!$D$2:$D$1001,MATCH($B33,智能流水!$B$2:$B$1001,0)),"")) | E33: =IF($B33="","",IFERROR(INDEX(智能流水!$E$2:$E$1001,MATCH($B33,智能流水!$B$2:$B$1001,0)),"")) | F33: =IF($B33="","",IFERROR(INDEX(智能流水!$F$2:$F$1001,MATCH($B33,智能流水!$B$2:$B$1001,0)),"")) | G33: =IF($B33="","",IFERROR(INDEX(智能流水!$G$2:$G$1001,MATCH($B33,智能流水!$B$2:$B$1001,0)),"")) | H33: =IF($B33="","",IFERROR(INDEX(智能流水!$H$2:$H$1001,MATCH($B33,智能流水!$B$2:$B$1001,0)),"")) | I33: =IF($B33="","",IFERROR(INDEX(智能流水!$I$2:$I$1001,MATCH($B33,智能流水!$B$2:$B$1001,0)),"")) | J33: =IF($B33="","",IFERROR(INDEX(智能流水!$J$2:$J$1001,MATCH($B33,智能流水!$B$2:$B$1001,0)),"")) | K33: =IF($B33="","",IFERROR(INDEX(智能流水!$K$2:$K$1001,MATCH($B33,智能流水!$B$2:$B$1001,0)),"")) | L33: =IF($B33="","",IFERROR(INDEX(智能流水!$L$2:$L$1001,MATCH($B33,智能流水!$B$2:$B$1001,0)),"")) | M33: =IF($B33="","",IFERROR(INDEX(智能流水!$M$2:$M$1001,MATCH($B33,智能流水!$B$2:$B$1001,0)),"")) | N33: =IF($B33="","",IFERROR(INDEX(智能流水!$N$2:$N$1001,MATCH($B33,智能流水!$B$2:$B$1001,0)),"")) | O33: =IF($B33="","",IFERROR(INDEX(智能流水!$O$2:$O$1001,MATCH($B33,智能流水!$B$2:$B$1001,0)),""))
A34: =IF($B34="","",33) | B34: =IFERROR(LARGE(智能流水!$B$2:$B$1001,33),"") | C34: =IF($B34="","",IFERROR(INDEX(智能流水!$C$2:$C$1001,MATCH($B34,智能流水!$B$2:$B$1001,0)),"")) | D34: =IF($B34="","",IFERROR(INDEX(智能流水!$D$2:$D$1001,MATCH($B34,智能流水!$B$2:$B$1001,0)),"")) | E34: =IF($B34="","",IFERROR(INDEX(智能流水!$E$2:$E$1001,MATCH($B34,智能流水!$B$2:$B$1001,0)),"")) | F34: =IF($B34="","",IFERROR(INDEX(智能流水!$F$2:$F$1001,MATCH($B34,智能流水!$B$2:$B$1001,0)),"")) | G34: =IF($B34="","",IFERROR(INDEX(智能流水!$G$2:$G$1001,MATCH($B34,智能流水!$B$2:$B$1001,0)),"")) | H34: =IF($B34="","",IFERROR(INDEX(智能流水!$H$2:$H$1001,MATCH($B34,智能流水!$B$2:$B$1001,0)),"")) | I34: =IF($B34="","",IFERROR(INDEX(智能流水!$I$2:$I$1001,MATCH($B34,智能流水!$B$2:$B$1001,0)),"")) | J34: =IF($B34="","",IFERROR(INDEX(智能流水!$J$2:$J$1001,MATCH($B34,智能流水!$B$2:$B$1001,0)),"")) | K34: =IF($B34="","",IFERROR(INDEX(智能流水!$K$2:$K$1001,MATCH($B34,智能流水!$B$2:$B$1001,0)),"")) | L34: =IF($B34="","",IFERROR(INDEX(智能流水!$L$2:$L$1001,MATCH($B34,智能流水!$B$2:$B$1001,0)),"")) | M34: =IF($B34="","",IFERROR(INDEX(智能流水!$M$2:$M$1001,MATCH($B34,智能流水!$B$2:$B$1001,0)),"")) | N34: =IF($B34="","",IFERROR(INDEX(智能流水!$N$2:$N$1001,MATCH($B34,智能流水!$B$2:$B$1001,0)),"")) | O34: =IF($B34="","",IFERROR(INDEX(智能流水!$O$2:$O$1001,MATCH($B34,智能流水!$B$2:$B$1001,0)),""))
A35: =IF($B35="","",34) | B35: =IFERROR(LARGE(智能流水!$B$2:$B$1001,34),"") | C35: =IF($B35="","",IFERROR(INDEX(智能流水!$C$2:$C$1001,MATCH($B35,智能流水!$B$2:$B$1001,0)),"")) | D35: =IF($B35="","",IFERROR(INDEX(智能流水!$D$2:$D$1001,MATCH($B35,智能流水!$B$2:$B$1001,0)),"")) | E35: =IF($B35="","",IFERROR(INDEX(智能流水!$E$2:$E$1001,MATCH($B35,智能流水!$B$2:$B$1001,0)),"")) | F35: =IF($B35="","",IFERROR(INDEX(智能流水!$F$2:$F$1001,MATCH($B35,智能流水!$B$2:$B$1001,0)),"")) | G35: =IF($B35="","",IFERROR(INDEX(智能流水!$G$2:$G$1001,MATCH($B35,智能流水!$B$2:$B$1001,0)),"")) | H35: =IF($B35="","",IFERROR(INDEX(智能流水!$H$2:$H$1001,MATCH($B35,智能流水!$B$2:$B$1001,0)),"")) | I35: =IF($B35="","",IFERROR(INDEX(智能流水!$I$2:$I$1001,MATCH($B35,智能流水!$B$2:$B$1001,0)),"")) | J35: =IF($B35="","",IFERROR(INDEX(智能流水!$J$2:$J$1001,MATCH($B35,智能流水!$B$2:$B$1001,0)),"")) | K35: =IF($B35="","",IFERROR(INDEX(智能流水!$K$2:$K$1001,MATCH($B35,智能流水!$B$2:$B$1001,0)),"")) | L35: =IF($B35="","",IFERROR(INDEX(智能流水!$L$2:$L$1001,MATCH($B35,智能流水!$B$2:$B$1001,0)),"")) | M35: =IF($B35="","",IFERROR(INDEX(智能流水!$M$2:$M$1001,MATCH($B35,智能流水!$B$2:$B$1001,0)),"")) | N35: =IF($B35="","",IFERROR(INDEX(智能流水!$N$2:$N$1001,MATCH($B35,智能流水!$B$2:$B$1001,0)),"")) | O35: =IF($B35="","",IFERROR(INDEX(智能流水!$O$2:$O$1001,MATCH($B35,智能流水!$B$2:$B$1001,0)),""))
A36: =IF($B36="","",35) | B36: =IFERROR(LARGE(智能流水!$B$2:$B$1001,35),"") | C36: =IF($B36="","",IFERROR(INDEX(智能流水!$C$2:$C$1001,MATCH($B36,智能流水!$B$2:$B$1001,0)),"")) | D36: =IF($B36="","",IFERROR(INDEX(智能流水!$D$2:$D$1001,MATCH($B36,智能流水!$B$2:$B$1001,0)),"")) | E36: =IF($B36="","",IFERROR(INDEX(智能流水!$E$2:$E$1001,MATCH($B36,智能流水!$B$2:$B$1001,0)),"")) | F36: =IF($B36="","",IFERROR(INDEX(智能流水!$F$2:$F$1001,MATCH($B36,智能流水!$B$2:$B$1001,0)),"")) | G36: =IF($B36="","",IFERROR(INDEX(智能流水!$G$2:$G$1001,MATCH($B36,智能流水!$B$2:$B$1001,0)),"")) | H36: =IF($B36="","",IFERROR(INDEX(智能流水!$H$2:$H$1001,MATCH($B36,智能流水!$B$2:$B$1001,0)),"")) | I36: =IF($B36="","",IFERROR(INDEX(智能流水!$I$2:$I$1001,MATCH($B36,智能流水!$B$2:$B$1001,0)),"")) | J36: =IF($B36="","",IFERROR(INDEX(智能流水!$J$2:$J$1001,MATCH($B36,智能流水!$B$2:$B$1001,0)),"")) | K36: =IF($B36="","",IFERROR(INDEX(智能流水!$K$2:$K$1001,MATCH($B36,智能流水!$B$2:$B$1001,0)),"")) | L36: =IF($B36="","",IFERROR(INDEX(智能流水!$L$2:$L$1001,MATCH($B36,智能流水!$B$2:$B$1001,0)),"")) | M36: =IF($B36="","",IFERROR(INDEX(智能流水!$M$2:$M$1001,MATCH($B36,智能流水!$B$2:$B$1001,0)),"")) | N36: =IF($B36="","",IFERROR(INDEX(智能流水!$N$2:$N$1001,MATCH($B36,智能流水!$B$2:$B$1001,0)),"")) | O36: =IF($B36="","",IFERROR(INDEX(智能流水!$O$2:$O$1001,MATCH($B36,智能流水!$B$2:$B$1001,0)),""))
A37: =IF($B37="","",36) | B37: =IFERROR(LARGE(智能流水!$B$2:$B$1001,36),"") | C37: =IF($B37="","",IFERROR(INDEX(智能流水!$C$2:$C$1001,MATCH($B37,智能流水!$B$2:$B$1001,0)),"")) | D37: =IF($B37="","",IFERROR(INDEX(智能流水!$D$2:$D$1001,MATCH($B37,智能流水!$B$2:$B$1001,0)),"")) | E37: =IF($B37="","",IFERROR(INDEX(智能流水!$E$2:$E$1001,MATCH($B37,智能流水!$B$2:$B$1001,0)),"")) | F37: =IF($B37="","",IFERROR(INDEX(智能流水!$F$2:$F$1001,MATCH($B37,智能流水!$B$2:$B$1001,0)),"")) | G37: =IF($B37="","",IFERROR(INDEX(智能流水!$G$2:$G$1001,MATCH($B37,智能流水!$B$2:$B$1001,0)),"")) | H37: =IF($B37="","",IFERROR(INDEX(智能流水!$H$2:$H$1001,MATCH($B37,智能流水!$B$2:$B$1001,0)),"")) | I37: =IF($B37="","",IFERROR(INDEX(智能流水!$I$2:$I$1001,MATCH($B37,智能流水!$B$2:$B$1001,0)),"")) | J37: =IF($B37="","",IFERROR(INDEX(智能流水!$J$2:$J$1001,MATCH($B37,智能流水!$B$2:$B$1001,0)),"")) | K37: =IF($B37="","",IFERROR(INDEX(智能流水!$K$2:$K$1001,MATCH($B37,智能流水!$B$2:$B$1001,0)),"")) | L37: =IF($B37="","",IFERROR(INDEX(智能流水!$L$2:$L$1001,MATCH($B37,智能流水!$B$2:$B$1001,0)),"")) | M37: =IF($B37="","",IFERROR(INDEX(智能流水!$M$2:$M$1001,MATCH($B37,智能流水!$B$2:$B$1001,0)),"")) | N37: =IF($B37="","",IFERROR(INDEX(智能流水!$N$2:$N$1001,MATCH($B37,智能流水!$B$2:$B$1001,0)),"")) | O37: =IF($B37="","",IFERROR(INDEX(智能流水!$O$2:$O$1001,MATCH($B37,智能流水!$B$2:$B$1001,0)),""))
A38: =IF($B38="","",37) | B38: =IFERROR(LARGE(智能流水!$B$2:$B$1001,37),"") | C38: =IF($B38="","",IFERROR(INDEX(智能流水!$C$2:$C$1001,MATCH($B38,智能流水!$B$2:$B$1001,0)),"")) | D38: =IF($B38="","",IFERROR(INDEX(智能流水!$D$2:$D$1001,MATCH($B38,智能流水!$B$2:$B$1001,0)),"")) | E38: =IF($B38="","",IFERROR(INDEX(智能流水!$E$2:$E$1001,MATCH($B38,智能流水!$B$2:$B$1001,0)),"")) | F38: =IF($B38="","",IFERROR(INDEX(智能流水!$F$2:$F$1001,MATCH($B38,智能流水!$B$2:$B$1001,0)),"")) | G38: =IF($B38="","",IFERROR(INDEX(智能流水!$G$2:$G$1001,MATCH($B38,智能流水!$B$2:$B$1001,0)),"")) | H38: =IF($B38="","",IFERROR(INDEX(智能流水!$H$2:$H$1001,MATCH($B38,智能流水!$B$2:$B$1001,0)),"")) | I38: =IF($B38="","",IFERROR(INDEX(智能流水!$I$2:$I$1001,MATCH($B38,智能流水!$B$2:$B$1001,0)),"")) | J38: =IF($B38="","",IFERROR(INDEX(智能流水!$J$2:$J$1001,MATCH($B38,智能流水!$B$2:$B$1001,0)),"")) | K38: =IF($B38="","",IFERROR(INDEX(智能流水!$K$2:$K$1001,MATCH($B38,智能流水!$B$2:$B$1001,0)),"")) | L38: =IF($B38="","",IFERROR(INDEX(智能流水!$L$2:$L$1001,MATCH($B38,智能流水!$B$2:$B$1001,0)),"")) | M38: =IF($B38="","",IFERROR(INDEX(智能流水!$M$2:$M$1001,MATCH($B38,智能流水!$B$2:$B$1001,0)),"")) | N38: =IF($B38="","",IFERROR(INDEX(智能流水!$N$2:$N$1001,MATCH($B38,智能流水!$B$2:$B$1001,0)),"")) | O38: =IF($B38="","",IFERROR(INDEX(智能流水!$O$2:$O$1001,MATCH($B38,智能流水!$B$2:$B$1001,0)),""))
A39: =IF($B39="","",38) | B39: =IFERROR(LARGE(智能流水!$B$2:$B$1001,38),"") | C39: =IF($B39="","",IFERROR(INDEX(智能流水!$C$2:$C$1001,MATCH($B39,智能流水!$B$2:$B$1001,0)),"")) | D39: =IF($B39="","",IFERROR(INDEX(智能流水!$D$2:$D$1001,MATCH($B39,智能流水!$B$2:$B$1001,0)),"")) | E39: =IF($B39="","",IFERROR(INDEX(智能流水!$E$2:$E$1001,MATCH($B39,智能流水!$B$2:$B$1001,0)),"")) | F39: =IF($B39="","",IFERROR(INDEX(智能流水!$F$2:$F$1001,MATCH($B39,智能流水!$B$2:$B$1001,0)),"")) | G39: =IF($B39="","",IFERROR(INDEX(智能流水!$G$2:$G$1001,MATCH($B39,智能流水!$B$2:$B$1001,0)),"")) | H39: =IF($B39="","",IFERROR(INDEX(智能流水!$H$2:$H$1001,MATCH($B39,智能流水!$B$2:$B$1001,0)),"")) | I39: =IF($B39="","",IFERROR(INDEX(智能流水!$I$2:$I$1001,MATCH($B39,智能流水!$B$2:$B$1001,0)),"")) | J39: =IF($B39="","",IFERROR(INDEX(智能流水!$J$2:$J$1001,MATCH($B39,智能流水!$B$2:$B$1001,0)),"")) | K39: =IF($B39="","",IFERROR(INDEX(智能流水!$K$2:$K$1001,MATCH($B39,智能流水!$B$2:$B$1001,0)),"")) | L39: =IF($B39="","",IFERROR(INDEX(智能流水!$L$2:$L$1001,MATCH($B39,智能流水!$B$2:$B$1001,0)),"")) | M39: =IF($B39="","",IFERROR(INDEX(智能流水!$M$2:$M$1001,MATCH($B39,智能流水!$B$2:$B$1001,0)),"")) | N39: =IF($B39="","",IFERROR(INDEX(智能流水!$N$2:$N$1001,MATCH($B39,智能流水!$B$2:$B$1001,0)),"")) | O39: =IF($B39="","",IFERROR(INDEX(智能流水!$O$2:$O$1001,MATCH($B39,智能流水!$B$2:$B$1001,0)),""))
A40: =IF($B40="","",39) | B40: =IFERROR(LARGE(智能流水!$B$2:$B$1001,39),"") | C40: =IF($B40="","",IFERROR(INDEX(智能流水!$C$2:$C$1001,MATCH($B40,智能流水!$B$2:$B$1001,0)),"")) | D40: =IF($B40="","",IFERROR(INDEX(智能流水!$D$2:$D$1001,MATCH($B40,智能流水!$B$2:$B$1001,0)),"")) | E40: =IF($B40="","",IFERROR(INDEX(智能流水!$E$2:$E$1001,MATCH($B40,智能流水!$B$2:$B$1001,0)),"")) | F40: =IF($B40="","",IFERROR(INDEX(智能流水!$F$2:$F$1001,MATCH($B40,智能流水!$B$2:$B$1001,0)),"")) | G40: =IF($B40="","",IFERROR(INDEX(智能流水!$G$2:$G$1001,MATCH($B40,智能流水!$B$2:$B$1001,0)),"")) | H40: =IF($B40="","",IFERROR(INDEX(智能流水!$H$2:$H$1001,MATCH($B40,智能流水!$B$2:$B$1001,0)),"")) | I40: =IF($B40="","",IFERROR(INDEX(智能流水!$I$2:$I$1001,MATCH($B40,智能流水!$B$2:$B$1001,0)),"")) | J40: =IF($B40="","",IFERROR(INDEX(智能流水!$J$2:$J$1001,MATCH($B40,智能流水!$B$2:$B$1001,0)),"")) | K40: =IF($B40="","",IFERROR(INDEX(智能流水!$K$2:$K$1001,MATCH($B40,智能流水!$B$2:$B$1001,0)),"")) | L40: =IF($B40="","",IFERROR(INDEX(智能流水!$L$2:$L$1001,MATCH($B40,智能流水!$B$2:$B$1001,0)),"")) | M40: =IF($B40="","",IFERROR(INDEX(智能流水!$M$2:$M$1001,MATCH($B40,智能流水!$B$2:$B$1001,0)),"")) | N40: =IF($B40="","",IFERROR(INDEX(智能流水!$N$2:$N$1001,MATCH($B40,智能流水!$B$2:$B$1001,0)),"")) | O40: =IF($B40="","",IFERROR(INDEX(智能流水!$O$2:$O$1001,MATCH($B40,智能流水!$B$2:$B$1001,0)),""))
...

Sheet 开奖记录
A1: 期号 | B1: 开奖时间 | C1: 第1码 | D1: 第2码 | E1: 第3码 | F1: 第4码 | G1: 第5码 | H1: 第6码 | I1: 特码 | J1: 年份生肖 | K1: 特码生肖 | L1: 特码波色
A2: 2026198 | B2: 2026-07-17 21:35:30 | C2: 48 | D2: 35 | E2: 45 | F2: 21 | G2: 12 | H2: 24 | I2: 07 | J2: 马 | K2: 鼠 | L2: 红波
A3: 2026197 | B3: 2026-07-16 21:35:30 | C3: 40 | D3: 19 | E3: 30 | F3: 48 | G3: 44 | H3: 28 | I3: 08 | J3: 马 | K3: 猪 | L3: 红波
A4: 2026196 | B4: 2026-07-15 21:35:30 | C4: 03 | D4: 37 | E4: 24 | F4: 10 | G4: 41 | H4: 19 | I4: 39 | J4: 马 | K4: 龙 | L4: 绿波
A5: 2026195 | B5: 2026-07-14 21:35:30 | C5: 46 | D5: 23 | E5: 39 | F5: 04 | G5: 09 | H5: 19 | I5: 25 | J5: 马 | K5: 马 | L5: 蓝波
A6: 2026194 | B6: 2026-07-13 21:35:29 | C6: 30 | D6: 21 | E6: 22 | F6: 15 | G6: 04 | H6: 34 | I6: 26 | J6: 马 | K6: 蛇 | L6: 蓝波
A7: 2026193 | B7: 2026-07-12 21:35:31 | C7: 02 | D7: 49 | E7: 25 | F7: 11 | G7: 45 | H7: 29 | I7: 09 | J7: 马 | K7: 狗 | L7: 蓝波
A8: 2026192 | B8: 2026-07-11 21:35:30 | C8: 27 | D8: 30 | E8: 45 | F8: 08 | G8: 01 | H8: 37 | I8: 25 | J8: 马 | K8: 马 | L8: 蓝波
A9: 2026191 | B9: 2026-07-10 21:35:30 | C9: 19 | D9: 43 | E9: 39 | F9: 24 | G9: 16 | H9: 26 | I9: 29 | J9: 马 | K9: 虎 | L9: 红波
A10: 2026190 | B10: 2026-07-09 21:35:30 | C10: 46 | D10: 14 | E10: 19 | F10: 37 | G10: 48 | H10: 29 | I10: 16 | J10: 马 | K10: 兔 | L10: 绿波
A11: 2026189 | B11: 2026-07-08 21:35:30 | C11: 45 | D11: 12 | E11: 37 | F11: 20 | G11: 38 | H11: 43 | I11: 15 | J11: 马 | K11: 龙 | L11: 蓝波
A12: 2026188 | B12: 2026-07-07 21:35:30 | C12: 38 | D12: 05 | E12: 19 | F12: 10 | G12: 14 | H12: 01 | I12: 16 | J12: 马 | K12: 兔 | L12: 绿波
A13: 2026187 | B13: 2026-07-06 21:35:30 | C13: 23 | D13: 12 | E13: 36 | F13: 38 | G13: 27 | H13: 22 | I13: 01 | J13: 马 | K13: 马 | L13: 红波
... A199: 2026001 | B199: 2026-01-01 21:35:33 | C199: 27 | D199: 08 | E199: 43 | F199: 33 | G199: 42 | H199: 11 | I199: 29 | J199: 蛇 | K199: 牛 | L199: 红波

Sheet 智能流水
A1: 序号 | B1: 期号 | C1: 原始记录 | D1: 命中金额 | E1: 亏损金额 | F1: 净额 | G1: 开奖时间 | H1: 实际特码 | I1: 实际生肖 | J1: 自动结果 | K1: 备注 | L1: 平码+5建议 | M1: 加5验算 | N1: 八肖建议 | O1: 八肖验算
A2: 1 | B2: 2026001 | C2: 牛 29 | D2: 1825 | F2: =IF(COUNTA(D2:E2)=0,"",N(D2)-N(E2)) | G2: =IFERROR(VLOOKUP($B2,'开奖记录'!$A:$K,2,FALSE),"") | H2: =IFERROR(VLOOKUP($B2,'开奖记录'!$A:$K,9,FALSE),"") | I2: =IFERROR(VLOOKUP($B2,'开奖记录'!$A:$K,11,FALSE),"") | J2: =IF($B2="","",IF(ISNUMBER($D2),"命中",IF(ISNUMBER($E2),"未命中",""))) | L2: =IFERROR(TEXT(VLOOKUP($B2-1,开奖记录!$A:$L,3,FALSE),"00")&"+5="&VLOOKUP(MOD(VLOOKUP($B2-1,开奖记录!$A:$L,3,FALSE)+4,49)+1,规律参数!$A:$C,3,FALSE),"") | M2: =IF(L2="","",IF(I2="","待开奖",IF(ISNUMBER(SEARCH(I2,L2)),"命中","未命中"))) | N2: =IFERROR(VLOOKUP(VLOOKUP($B2-1,开奖记录!$A:$L,11,FALSE),八肖参数!$A:$B,2,FALSE),"") | O2: =IF(N2="","",IF(I2="","待开奖",IF(ISNUMBER(SEARCH(I2,N2)),"命中","未命中")))
A3: 2 | B3: 2026002 | C3: 猴 22 | E3: 890 | F3: =IF(COUNTA(D3:E3)=0,"",N(D3)-N(E3)) | G3: =IFERROR(VLOOKUP($B3,'开奖记录'!$A:$K,2,FALSE),"") | H3: =IFERROR(VLOOKUP($B3,'开奖记录'!$A:$K,9,FALSE),"") | I3: =IFERROR(VLOOKUP($B3,'开奖记录'!$A:$K,11,FALSE),"") | J3: =IF($B3="","",IF(ISNUMBER($D3),"命中",IF(ISNUMBER($E3),"未命中",""))) | L3: =IFERROR(TEXT(VLOOKUP($B3-1,开奖记录!$A:$L,3,FALSE),"00")&"+5="&VLOOKUP(MOD(VLOOKUP($B3-1,开奖记录!$A:$L,3,FALSE)+4,49)+1,规律参数!$A:$C,3,FALSE),"") | M3: =IF(L3="","",IF(I3="","待开奖",IF(ISNUMBER(SEARCH(I3,L3)),"命中","未命中"))) | N3: =IFERROR(VLOOKUP(VLOOKUP($B3-1,开奖记录!$A:$L,11,FALSE),八肖参数!$A:$B,2,FALSE),"") | O3: =IF(N3="","",IF(I3="","待开奖",IF(ISNUMBER(SEARCH(I3,N3)),"命中","未命中")))
A4: 3 | B4: 2026003 | C4: 鸡 09 | E4: 980 | F4: =IF(COUNTA(D4:E4)=0,"",N(D4)-N(E4)) | G4: =IFERROR(VLOOKUP($B4,'开奖记录'!$A:$K,2,FALSE),"") | H4: =IFERROR(VLOOKUP($B4,'开奖记录'!$A:$K,9,FALSE),"") | I4: =IFERROR(VLOOKUP($B4,'开奖记录'!$A:$K,11,FALSE),"") | J4: =IF($B4="","",IF(ISNUMBER($D4),"命中",IF(ISNUMBER($E4),"未命中",""))) | L4: =IFERROR(TEXT(VLOOKUP($B4-1,开奖记录!$A:$L,3,FALSE),"00")&"+5="&VLOOKUP(MOD(VLOOKUP($B4-1,开奖记录!$A:$L,3,FALSE)+4,49)+1,规律参数!$A:$C,3,FALSE),"") | M4: =IF(L4="","",IF(I4="","待开奖",IF(ISNUMBER(SEARCH(I4,L4)),"命中","未命中"))) | N4: =IFERROR(VLOOKUP(VLOOKUP($B4-1,开奖记录!$A:$L,11,FALSE),八肖参数!$A:$B,2,FALSE),"") | O4: =IF(N4="","",IF(I4="","待开奖",IF(ISNUMBER(SEARCH(I4,N4)),"命中","未命中")))
A5: 4 | B5: 2026004 | C5: 鸡 45 | E5: 750 | F5: =IF(COUNTA(D5:E5)=0,"",N(D5)-N(E5)) | G5: =IFERROR(VLOOKUP($B5,'开奖记录'!$A:$K,2,FALSE),"") | H5: =IFERROR(VLOOKUP($B5,'开奖记录'!$A:$K,9,FALSE),"") | I5: =IFERROR(VLOOKUP($B5,'开奖记录'!$A:$K,11,FALSE),"") | J5: =IF($B5="","",IF(ISNUMBER($D5),"命中",IF(ISNUMBER($E5),"未命中",""))) | L5: =IFERROR(TEXT(VLOOKUP($B5-1,开奖记录!$A:$L,3,FALSE),"00")&"+5="&VLOOKUP(MOD(VLOOKUP($B5-1,开奖记录!$A:$L,3,FALSE)+4,49)+1,规律参数!$A:$C,3,FALSE),"") | M5: =IF(L5="","",IF(I5="","待开奖",IF(ISNUMBER(SEARCH(I5,L5)),"命中","未命中"))) | N5: =IFERROR(VLOOKUP(VLOOKUP($B5-1,开奖记录!$A:$L,11,FALSE),八肖参数!$A:$B,2,FALSE),"") | O5: =IF(N5="","",IF(I5="","待开奖",IF(ISNUMBER(SEARCH(I5,N5)),"命中","未命中")))
A6: 5 | B6: 2026005 | C6: 猪 43 | E6: 540 | F6: =IF(COUNTA(D6:E6)=0,"",N(D6)-N(E6)) | G6: =IFERROR(VLOOKUP($B6,'开奖记录'!$A:$K,2,FALSE),"") | H6: =IFERROR(VLOOKUP($B6,'开奖记录'!$A:$K,9,FALSE),"") | I6: =IFERROR(VLOOKUP($B6,'开奖记录'!$A:$K,11,FALSE),"") | J6: =IF($B6="","",IF(ISNUMBER($D6),"命中",IF(ISNUMBER($E6),"未命中",""))) | L6: =IFERROR(TEXT(VLOOKUP($B6-1,开奖记录!$A:$L,3,FALSE),"00")&"+5="&VLOOKUP(MOD(VLOOKUP($B6-1,开奖记录!$A:$L,3,FALSE)+4,49)+1,规律参数!$A:$C,3,FALSE),"") | M6: =IF(L6="","",IF(I6="","待开奖",IF(ISNUMBER(SEARCH(I6,L6)),"命中","未命中"))) | N6: =IFERROR(VLOOKUP(VLOOKUP($B6-1,开奖记录!$A:$L,11,FALSE),八肖参数!$A:$B,2,FALSE),"") | O6: =IF(N6="","",IF(I6="","待开奖",IF(ISNUMBER(SEARCH(I6,N6)),"命中","未命中")))
A7: 6 | B7: 2026006 | C7: 蛇 13 | D7: 1065 | F7: =IF(COUNTA(D7:E7)=0,"",N(D7)-N(E7)) | G7: =IFERROR(VLOOKUP($B7,'开奖记录'!$A:$K,2,FALSE),"") | H7: =IFERROR(VLOOKUP($B7,'开奖记录'!$A:$K,9,FALSE),"") | I7: =IFERROR(VLOOKUP($B7,'开奖记录'!$A:$K,11,FALSE),"") | J7: =IF($B7="","",IF(ISNUMBER($D7),"命中",IF(ISNUMBER($E7),"未命中",""))) | L7: =IFERROR(TEXT(VLOOKUP($B7-1,开奖记录!$A:$L,3,FALSE),"00")&"+5="&VLOOKUP(MOD(VLOOKUP($B7-1,开奖记录!$A:$L,3,FALSE)+4,49)+1,规律参数!$A:$C,3,FALSE),"") | M7: =IF(L7="","",IF(I7="","待开奖",IF(ISNUMBER(SEARCH(I7,L7)),"命中","未命中"))) | N7: =IFERROR(VLOOKUP(VLOOKUP($B7-1,开奖记录!$A:$L,11,FALSE),八肖参数!$A:$B,2,FALSE),"") | O7: =IF(N7="","",IF(I7="","待开奖",IF(ISNUMBER(SEARCH(I7,N7)),"命中","未命中")))
A8: 7 | B8: 2026007 | C8: 牛 41 | D8: 765 | F8: =IF(COUNTA(D8:E8)=0,"",N(D8)-N(E8)) | G8: =IFERROR(VLOOKUP($B8,'开奖记录'!$A:$K,2,FALSE),"") | H8: =IFERROR(VLOOKUP($B8,'开奖记录'!$A:$K,9,FALSE),"") | I8: =IFERROR(VLOOKUP($B8,'开奖记录'!$A:$K,11,FALSE),"") | J8: =IF($B8="","",IF(ISNUMBER($D8),"命中",IF(ISNUMBER($E8),"未命中",""))) | L8: =IFERROR(TEXT(VLOOKUP($B8-1,开奖记录!$A:$L,3,FALSE),"00")&"+5="&VLOOKUP(MOD(VLOOKUP($B8-1,开奖记录!$A:$L,3,FALSE)+4,49)+1,规律参数!$A:$C,3,FALSE),"") | M8: =IF(L8="","",IF(I8="","待开奖",IF(ISNUMBER(SEARCH(I8,L8)),"命中","未命中"))) | N8: =IFERROR(VLOOKUP(VLOOKUP($B8-1,开奖记录!$A:$L,11,FALSE),八肖参数!$A:$B,2,FALSE),"") | O8: =IF(N8="","",IF(I8="","待开奖",IF(ISNUMBER(SEARCH(I8,N8)),"命中","未命中")))
A9: 8 | B9: 2026008 | C9: 鸡 21 | D9: 2870 | F9: =IF(COUNTA(D9:E9)=0,"",N(D9)-N(E9)) | G9: =IFERROR(VLOOKUP($B9,'开奖记录'!$A:$K,2,FALSE),"") | H9: =IFERROR(VLOOKUP($B9,'开奖记录'!$A:$K,9,FALSE),"") | I9: =IFERROR(VLOOKUP($B9,'开奖记录'!$A:$K,11,FALSE),"") | J9: =IF($B9="","",IF(ISNUMBER($D9),"命中",IF(ISNUMBER($E9),"未命中",""))) | L9: =IFERROR(TEXT(VLOOKUP($B9-1,开奖记录!$A:$L,3,FALSE),"00")&"+5="&VLOOKUP(MOD(VLOOKUP($B9-1,开奖记录!$A:$L,3,FALSE)+4,49)+1,规律参数!$A:$C,3,FALSE),"") | M9: =IF(L9="","",IF(I9="","待开奖",IF(ISNUMBER(SEARCH(I9,L9)),"命中","未命中"))) | N9: =IFERROR(VLOOKUP(VLOOKUP($B9-1,开奖记录!$A:$L,11,FALSE),八肖参数!$A:$B,2,FALSE),"") | O9: =IF(N9="","",IF(I9="","待开奖",IF(ISNUMBER(SEARCH(I9,N9)),"命中","未命中")))
A10: 9 | B10: 2026009 | C10: 虎 28 | E10: 880 | F10: =IF(COUNTA(D10:E10)=0,"",N(D10)-N(E10)) | G10: =IFERROR(VLOOKUP($B10,'开奖记录'!$A:$K,2,FALSE),"") | H10: =IFERROR(VLOOKUP($B10,'开奖记录'!$A:$K,9,FALSE),"") | I10: =IFERROR(VLOOKUP($B10,'开奖记录'!$A:$K,11,FALSE),"") | J10: =IF($B10="","",IF(ISNUMBER($D10),"命中",IF(ISNUMBER($E10),"未命中",""))) | L10: =IFERROR(TEXT(VLOOKUP($B10-1,开奖记录!$A:$L,3,FALSE),"00")&"+5="&VLOOKUP(MOD(VLOOKUP($B10-1,开奖记录!$A:$L,3,FALSE)+4,49)+1,规律参数!$A:$C,3,FALSE),"") | M10: =IF(L10="","",IF(I10="","待开奖",IF(ISNUMBER(SEARCH(I10,L10)),"命中","未命中"))) | N10: =IFERROR(VLOOKUP(VLOOKUP($B10-1,开奖记录!$A:$L,11,FALSE),八肖参数!$A:$B,2,FALSE),"") | O10: =IF(N10="","",IF(I10="","待开奖",IF(ISNUMBER(SEARCH(I10,N10)),"命中","未命中")))
A11: 10 | B11: 2026010 | C11: 兔 27 | D11: 130 | F11: =IF(COUNTA(D11:E11)=0,"",N(D11)-N(E11)) | G11: =IFERROR(VLOOKUP($B11,'开奖记录'!$A:$K,2,FALSE),"") | H11: =IFERROR(VLOOKUP($B11,'开奖记录'!$A:$K,9,FALSE),"") | I11: =IFERROR(VLOOKUP($B11,'开奖记录'!$A:$K,11,FALSE),"") | J11: =IF($B11="","",IF(ISNUMBER($D11),"命中",IF(ISNUMBER($E11),"未命中",""))) | L11: =IFERROR(TEXT(VLOOKUP($B11-1,开奖记录!$A:$L,3,FALSE),"00")&"+5="&VLOOKUP(MOD(VLOOKUP($B11-1,开奖记录!$A:$L,3,FALSE)+4,49)+1,规律参数!$A:$C,3,FALSE),"") | M11: =IF(L11="","",IF(I11="","待开奖",IF(ISNUMBER(SEARCH(I11,L11)),"命中","未命中"))) | N11: =IFERROR(VLOOKUP(VLOOKUP($B11-1,开奖记录!$A:$L,11,FALSE),八肖参数!$A:$B,2,FALSE),"") | O11: =IF(N11="","",IF(I11="","待开奖",IF(ISNUMBER(SEARCH(I11,N11)),"命中","未命中")))
A12: 11 | B12: 2026011 | C12: 羊 11 | E12: 330 | F12: =IF(COUNTA(D12:E12)=0,"",N(D12)-N(E12)) | G12: =IFERROR(VLOOKUP($B12,'开奖记录'!$A:$K,2,FALSE),"") | H12: =IFERROR(VLOOKUP($B12,'开奖记录'!$A:$K,9,FALSE),"") | I12: =IFERROR(VLOOKUP($B12,'开奖记录'!$A:$K,11,FALSE),"") | J12: =IF($B12="","",IF(ISNUMBER($D12),"命中",IF(ISNUMBER($E12),"未命中",""))) | L12: =IFERROR(TEXT(VLOOKUP($B12-1,开奖记录!$A:$L,3,FALSE),"00")&"+5="&VLOOKUP(MOD(VLOOKUP($B12-1,开奖记录!$A:$L,3,FALSE)+4,49)+1,规律参数!$A:$C,3,FALSE),"") | M12: =IF(L12="","",IF(I12="","待开奖",IF(ISNUMBER(SEARCH(I12,L12)),"命中","未命中"))) | N12: =IFERROR(VLOOKUP(VLOOKUP($B12-1,开奖记录!$A:$L,11,FALSE),八肖参数!$A:$B,2,FALSE),"") | O12: =IF(N12="","",IF(I12="","待开奖",IF(ISNUMBER(SEARCH(I12,N12)),"命中","未命中")))
A13: 12 | B13: 2026012 | C13: 羊 11 | E13: 450 | F13: =IF(COUNTA(D13:E13)=0,"",N(D13)-N(E13)) | G13: =IFERROR(VLOOKUP($B13,'开奖记录'!$A:$K,2,FALSE),"") | H13: =IFERROR(VLOOKUP($B13,'开奖记录'!$A:$K,9,FALSE),"") | I13: =IFERROR(VLOOKUP($B13,'开奖记录'!$A:$K,11,FALSE),"") | J13: =IF($B13="","",IF(ISNUMBER($D13),"命中",IF(ISNUMBER($E13),"未命中",""))) | L13: =IFERROR(TEXT(VLOOKUP($B13-1,开奖记录!$A:$L,3,FALSE),"00")&"+5="&VLOOKUP(MOD(VLOOKUP($B13-1,开奖记录!$A:$L,3,FALSE)+4,49)+1,规律参数!$A:$C,3,FALSE),"") | M13: =IF(L13="","",IF(I13="","待开奖",IF(ISNUMBER(SEARCH(I13,L13)),"命中","未命中"))) | N13: =IFERROR(VLOOKUP(VLOOKUP($B13-1,开奖记录!$A:$L,11,FALSE),八肖参数!$A:$B,2,FALSE),"") | O13: =IF(N13="","",IF(I13="","待开奖",IF(ISNUMBER(SEARCH(I13,N13)),"命中","未命中")))
